{
  "version": 8,
  "blockIdVersion": 11,
  "anchorX": 0,
  "anchorY": 0,
  "anchorZ": 0,
  "blocks": [
    {
      "x": -115,
      "y": 33,
      "z": -84,
      "name": "Cloth_Block_Wool_Gray_Light"
    },
    {
      "x": -115,
      "y": 33,
      "z": -83,
      "name": "Cloth_Block_Wool_Gray_Light"
    },
    {
      "x": -115,
      "y": 33,
      "z": -82,
      "name": "Cloth_Block_Wool_Gray_Light"
    },
    {
      "x": -115,
      "y": 33,
      "z": -81,
      "name": "Cloth_Block_Wool_Gray_Light"
    },
    {
      "x": -115,
      "y": 33,
      "z": -80,
      "name": "Cloth_Block_Wool_Gray_Light"
    },
    {
      "x": -115,
      "y": 33,
      "z": -79,
      "name": "Cloth_Block_Wool_Gray_Light"
    },
    {
      "x": -115,
      "y": 33,
      "z": -78,
      "name": "Cloth_Block_Wool_Gray_Light"
    },
    {
      "x": -115,
      "y": 33,
      "z": -77,
      "name": "Cloth_Block_Wool_Gray_Light"
    },
    {
      "x": -115,
      "y": 33,
      "z": -76,
      "name": "Cloth_Block_Wool_Gray_Light"
    },
    {
      "x": -115,
      "y": 33,
      "z": -75,
      "name": "Cloth_Block_Wool_Gray_Light"
    },
    {
      "x": -115,
      "y": 33,
      "z": -74,
      "name": "Cloth_Block_Wool_Gray_Light"
    },
    {
      "x": -115,
      "y": 33,
      "z": -73,
      "name": "Cloth_Block_Wool_Gray_Light"
    },
    {
      "x": -115,
      "y": 33,
      "z": -72,
      "name": "Cloth_Block_Wool_Gray_Light"
    },
    {
      "x": -115,
      "y": 33,
      "z": -71,
      "name": "Cloth_Block_Wool_Gray_Light"
    },
    {
      "x": -115,
      "y": 33,
      "z": -70,
      "name": "Cloth_Block_Wool_Gray_Light"
    },
    {
      "x": -115,
      "y": 33,
      "z": -69,
      "name": "Cloth_Block_Wool_Gray_Light"
    },
    {
      "x": -115,
      "y": 33,
      "z": -68,
      "name": "Cloth_Block_Wool_Gray_Light"
    },
    {
      "x": -115,
      "y": 33,
      "z": -67,
      "name": "Cloth_Block_Wool_Gray_Light"
    },
    {
      "x": -115,
      "y": 33,
      "z": -66,
      "name": "Cloth_Block_Wool_Gray_Light"
    },
    {
      "x": -115,
      "y": 33,
      "z": -65,
      "name": "Cloth_Block_Wool_Gray_Light"
    },
    {
      "x": -115,
      "y": 33,
      "z": -64,
      "name": "Cloth_Block_Wool_Gray_Light"
    },
    {
      "x": -115,
      "y": 33,
      "z": -63,
      "name": "Cloth_Block_Wool_Gray_Light"
    },
    {
      "x": -115,
      "y": 33,
      "z": -62,
      "name": "Cloth_Block_Wool_Gray_Light"
    },
    {
      "x": -115,
      "y": 33,
      "z": -61,
      "name": "Cloth_Block_Wool_Gray_Light"
    },
    {
      "x": -115,
      "y": 33,
      "z": -60,
      "name": "Cloth_Block_Wool_Gray_Light"
    },
    {
      "x": -115,
      "y": 33,
      "z": -59,
      "name": "Cloth_Block_Wool_Gray_Light"
    },
    {
      "x": -115,
      "y": 33,
      "z": -58,
      "name": "Cloth_Block_Wool_Gray_Light"
    },
    {
      "x": -115,
      "y": 33,
      "z": -57,
      "name": "Cloth_Block_Wool_Gray_Light"
    },
    {
      "x": -115,
      "y": 33,
      "z": -56,
      "name": "Cloth_Block_Wool_Gray_Light"
    },
    {
      "x": -115,
      "y": 33,
      "z": -55,
      "name": "Cloth_Block_Wool_Gray_Light"
    },
    {
      "x": -115,
      "y": 33,
      "z": -54,
      "name": "Cloth_Block_Wool_Gray_Light"
    },
    {
      "x": -115,
      "y": 33,
      "z": -53,
      "name": "Cloth_Block_Wool_Gray_Light"
    },
    {
      "x": -115,
      "y": 33,
      "z": -52,
      "name": "Cloth_Block_Wool_Gray_Light"
    },
    {
      "x": -115,
      "y": 33,
      "z": -51,
      "name": "Cloth_Block_Wool_Gray_Light"
    },
    {
      "x": -115,
      "y": 33,
      "z": -50,
      "name": "Cloth_Block_Wool_Gray_Light"
    },
    {
      "x": -115,
      "y": 33,
      "z": -49,
      "name": "Cloth_Block_Wool_Gray_Light"
    },
    {
      "x": -115,
      "y": 33,
      "z": -48,
      "name": "Cloth_Block_Wool_Gray_Light"
    },
    {
      "x": -115,
      "y": 33,
      "z": -47,
      "name": "Cloth_Block_Wool_Gray_Light"
    },
    {
      "x": -115,
      "y": 33,
      "z": -46,
      "name": "Cloth_Block_Wool_Gray_Light"
    },
    {
      "x": -115,
      "y": 33,
      "z": -45,
      "name": "Cloth_Block_Wool_Gray_Light"
    },
    {
      "x": -115,
      "y": 33,
      "z": -44,
      "name": "Cloth_Block_Wool_Gray_Light"
    },
    {
      "x": -115,
      "y": 33,
      "z": -43,
      "name": "Cloth_Block_Wool_Gray_Light"
    },
    {
      "x": -115,
      "y": 33,
      "z": -42,
      "name": "Cloth_Block_Wool_Gray_Light"
    },
    {
      "x": -115,
      "y": 33,
      "z": -41,
      "name": "Cloth_Block_Wool_Gray_Light"
    },
    {
      "x": -115,
      "y": 33,
      "z": -40,
      "name": "Cloth_Block_Wool_Gray_Light"
    },
    {
      "x": -115,
      "y": 33,
      "z": -39,
      "name": "Cloth_Block_Wool_Gray_Light"
    },
    {
      "x": -115,
      "y": 33,
      "z": -38,
      "name": "Cloth_Block_Wool_Gray_Light"
    },
    {
      "x": -115,
      "y": 33,
      "z": -37,
      "name": "Cloth_Block_Wool_Gray_Light"
    },
    {
      "x": -115,
      "y": 33,
      "z": -36,
      "name": "Cloth_Block_Wool_Gray_Light"
    },
    {
      "x": -115,
      "y": 33,
      "z": -35,
      "name": "Cloth_Block_Wool_Gray_Light"
    },
    {
      "x": -115,
      "y": 33,
      "z": -34,
      "name": "Cloth_Block_Wool_Gray_Light"
    },
    {
      "x": -115,
      "y": 33,
      "z": -33,
      "name": "Cloth_Block_Wool_Gray_Light"
    },
    {
      "x": -115,
      "y": 33,
      "z": -32,
      "name": "Cloth_Block_Wool_Gray_Light"
    },
    {
      "x": -115,
      "y": 33,
      "z": -31,
      "name": "Cloth_Block_Wool_Gray_Light"
    },
    {
      "x": -115,
      "y": 33,
      "z": -30,
      "name": "Cloth_Block_Wool_Gray_Light"
    },
    {
      "x": -115,
      "y": 33,
      "z": -29,
      "name": "Cloth_Block_Wool_Gray_Light"
    },
    {
      "x": -115,
      "y": 33,
      "z": -28,
      "name": "Cloth_Block_Wool_Gray_Light"
    },
    {
      "x": -115,
      "y": 33,
      "z": -27,
      "name": "Cloth_Block_Wool_Gray_Light"
    },
    {
      "x": -115,
      "y": 33,
      "z": -26,
      "name": "Cloth_Block_Wool_Gray_Light"
    },
    {
      "x": -115,
      "y": 33,
      "z": -25,
      "name": "Cloth_Block_Wool_Gray_Light"
    },
    {
      "x": -115,
      "y": 33,
      "z": -24,
      "name": "Cloth_Block_Wool_Gray_Light"
    },
    {
      "x": -115,
      "y": 33,
      "z": -23,
      "name": "Cloth_Block_Wool_Gray_Light"
    },
    {
      "x": -115,
      "y": 33,
      "z": -22,
      "name": "Cloth_Block_Wool_Gray_Light"
    },
    {
      "x": -115,
      "y": 33,
      "z": -21,
      "name": "Cloth_Block_Wool_Gray_Light"
    },
    {
      "x": -115,
      "y": 33,
      "z": -20,
      "name": "Cloth_Block_Wool_Gray_Light"
    },
    {
      "x": -115,
      "y": 33,
      "z": -19,
      "name": "Cloth_Block_Wool_Gray_Light"
    },
    {
      "x": -115,
      "y": 33,
      "z": -18,
      "name": "Cloth_Block_Wool_Gray_Light"
    },
    {
      "x": -115,
      "y": 33,
      "z": -17,
      "name": "Cloth_Block_Wool_Gray_Light"
    },
    {
      "x": -115,
      "y": 33,
      "z": -16,
      "name": "Cloth_Block_Wool_Gray_Light"
    },
    {
      "x": -115,
      "y": 33,
      "z": -15,
      "name": "Cloth_Block_Wool_Gray_Light"
    },
    {
      "x": -115,
      "y": 33,
      "z": -14,
      "name": "Cloth_Block_Wool_Gray_Light"
    },
    {
      "x": -115,
      "y": 33,
      "z": -13,
      "name": "Cloth_Block_Wool_Gray_Light"
    },
    {
      "x": -115,
      "y": 33,
      "z": -12,
      "name": "Cloth_Block_Wool_Gray_Light"
    },
    {
      "x": -115,
      "y": 33,
      "z": -11,
      "name": "Cloth_Block_Wool_Gray_Light"
    },
    {
      "x": -115,
      "y": 33,
      "z": -10,
      "name": "Cloth_Block_Wool_Gray_Light"
    },
    {
      "x": -115,
      "y": 33,
      "z": -9,
      "name": "Cloth_Block_Wool_Gray_Light"
    },
    {
      "x": -115,
      "y": 33,
      "z": -8,
      "name": "Cloth_Block_Wool_Gray_Light"
    },
    {
      "x": -115,
      "y": 33,
      "z": -7,
      "name": "Cloth_Block_Wool_Gray_Light"
    },
    {
      "x": -115,
      "y": 33,
      "z": -6,
      "name": "Cloth_Block_Wool_Gray_Light"
    },
    {
      "x": -115,
      "y": 33,
      "z": -5,
      "name": "Cloth_Block_Wool_Gray_Light"
    },
    {
      "x": -115,
      "y": 33,
      "z": -4,
      "name": "Cloth_Block_Wool_Gray_Light"
    },
    {
      "x": -115,
      "y": 33,
      "z": -3,
      "name": "Cloth_Block_Wool_Gray_Light"
    },
    {
      "x": -115,
      "y": 33,
      "z": -2,
      "name": "Cloth_Block_Wool_Gray_Light"
    },
    {
      "x": -115,
      "y": 33,
      "z": -1,
      "name": "Cloth_Block_Wool_Gray_Light"
    },
    {
      "x": -115,
      "y": 33,
      "z": 0,
      "name": "Cloth_Block_Wool_Gray_Light"
    },
    {
      "x": -115,
      "y": 33,
      "z": 1,
      "name": "Cloth_Block_Wool_Gray_Light"
    },
    {
      "x": -115,
      "y": 33,
      "z": 2,
      "name": "Cloth_Block_Wool_Gray_Light"
    },
    {
      "x": -115,
      "y": 33,
      "z": 3,
      "name": "Cloth_Block_Wool_Gray_Light"
    },
    {
      "x": -115,
      "y": 33,
      "z": 4,
      "name": "Cloth_Block_Wool_Gray_Light"
    },
    {
      "x": -115,
      "y": 33,
      "z": 5,
      "name": "Cloth_Block_Wool_Gray_Light"
    },
    {
      "x": -115,
      "y": 33,
      "z": 6,
      "name": "Cloth_Block_Wool_Gray_Light"
    },
    {
      "x": -115,
      "y": 33,
      "z": 7,
      "name": "Cloth_Block_Wool_Gray_Light"
    },
    {
      "x": -115,
      "y": 33,
      "z": 8,
      "name": "Cloth_Block_Wool_Gray_Light"
    },
    {
      "x": -115,
      "y": 33,
      "z": 9,
      "name": "Cloth_Block_Wool_Gray_Light"
    },
    {
      "x": -115,
      "y": 33,
      "z": 10,
      "name": "Cloth_Block_Wool_Gray_Light"
    },
    {
      "x": -115,
      "y": 33,
      "z": 11,
      "name": "Cloth_Block_Wool_Gray_Light"
    },
    {
      "x": -115,
      "y": 33,
      "z": 12,
      "name": "Cloth_Block_Wool_Gray_Light"
    },
    {
      "x": -115,
      "y": 33,
      "z": 13,
      "name": "Cloth_Block_Wool_Gray_Light"
    },
    {
      "x": -115,
      "y": 33,
      "z": 14,
      "name": "Cloth_Block_Wool_Gray_Light"
    },
    {
      "x": -115,
      "y": 33,
      "z": 15,
      "name": "Cloth_Block_Wool_Gray_Light"
    },
    {
      "x": -115,
      "y": 33,
      "z": 16,
      "name": "Cloth_Block_Wool_Gray_Light"
    },
    {
      "x": -115,
      "y": 33,
      "z": 17,
      "name": "Cloth_Block_Wool_Gray_Light"
    },
    {
      "x": -115,
      "y": 33,
      "z": 18,
      "name": "Cloth_Block_Wool_Gray_Light"
    },
    {
      "x": -115,
      "y": 33,
      "z": 19,
      "name": "Cloth_Block_Wool_Gray_Light"
    },
    {
      "x": -115,
      "y": 33,
      "z": 20,
      "name": "Cloth_Block_Wool_Gray_Light"
    },
    {
      "x": -115,
      "y": 33,
      "z": 21,
      "name": "Cloth_Block_Wool_Gray_Light"
    },
    {
      "x": -115,
      "y": 33,
      "z": 22,
      "name": "Cloth_Block_Wool_Gray_Light"
    },
    {
      "x": -115,
      "y": 33,
      "z": 23,
      "name": "Cloth_Block_Wool_Gray_Light"
    },
    {
      "x": -115,
      "y": 33,
      "z": 24,
      "name": "Cloth_Block_Wool_Gray_Light"
    },
    {
      "x": -115,
      "y": 33,
      "z": 25,
      "name": "Cloth_Block_Wool_Gray_Light"
    },
    {
      "x": -115,
      "y": 33,
      "z": 26,
      "name": "Cloth_Block_Wool_Gray_Light"
    },
    {
      "x": -115,
      "y": 33,
      "z": 27,
      "name": "Cloth_Block_Wool_Gray_Light"
    },
    {
      "x": -115,
      "y": 33,
      "z": 28,
      "name": "Cloth_Block_Wool_Gray_Light"
    },
    {
      "x": -115,
      "y": 33,
      "z": 29,
      "name": "Cloth_Block_Wool_Gray_Light"
    },
    {
      "x": -115,
      "y": 33,
      "z": 30,
      "name": "Cloth_Block_Wool_Gray_Light"
    },
    {
      "x": -115,
      "y": 33,
      "z": 31,
      "name": "Cloth_Block_Wool_Gray_Light"
    },
    {
      "x": -115,
      "y": 33,
      "z": 32,
      "name": "Cloth_Block_Wool_Gray_Light"
    },
    {
      "x": -115,
      "y": 33,
      "z": 33,
      "name": "Cloth_Block_Wool_Gray_Light"
    },
    {
      "x": -115,
      "y": 33,
      "z": 34,
      "name": "Cloth_Block_Wool_Gray_Light"
    },
    {
      "x": -115,
      "y": 40,
      "z": 34,
      "name": "Plant_Leaves_Jungle"
    },
    {
      "x": -115,
      "y": 33,
      "z": 35,
      "name": "Cloth_Block_Wool_Gray_Light"
    },
    {
      "x": -115,
      "y": 40,
      "z": 35,
      "name": "Plant_Leaves_Jungle"
    },
    {
      "x": -115,
      "y": 41,
      "z": 35,
      "name": "Plant_Leaves_Jungle"
    },
    {
      "x": -115,
      "y": 33,
      "z": 36,
      "name": "Cloth_Block_Wool_Gray_Light"
    },
    {
      "x": -115,
      "y": 40,
      "z": 36,
      "name": "Wood_Jungle_Trunk_Full"
    },
    {
      "x": -115,
      "y": 41,
      "z": 36,
      "name": "Plant_Leaves_Jungle"
    },
    {
      "x": -115,
      "y": 33,
      "z": 37,
      "name": "Cloth_Block_Wool_Gray_Light"
    },
    {
      "x": -115,
      "y": 40,
      "z": 37,
      "name": "Wood_Jungle_Trunk_Full"
    },
    {
      "x": -115,
      "y": 41,
      "z": 37,
      "name": "Plant_Leaves_Jungle"
    },
    {
      "x": -115,
      "y": 33,
      "z": 38,
      "name": "Cloth_Block_Wool_Gray_Light"
    },
    {
      "x": -115,
      "y": 41,
      "z": 38,
      "name": "Plant_Leaves_Jungle"
    },
    {
      "x": -115,
      "y": 33,
      "z": 39,
      "name": "Cloth_Block_Wool_Gray_Light"
    },
    {
      "x": -115,
      "y": 33,
      "z": 40,
      "name": "Cloth_Block_Wool_Gray_Light"
    },
    {
      "x": -115,
      "y": 39,
      "z": 40,
      "name": "Plant_Leaves_Jungle"
    },
    {
      "x": -115,
      "y": 40,
      "z": 40,
      "name": "Plant_Leaves_Jungle"
    },
    {
      "x": -115,
      "y": 33,
      "z": 41,
      "name": "Cloth_Block_Wool_Gray_Light"
    },
    {
      "x": -115,
      "y": 39,
      "z": 41,
      "name": "Plant_Leaves_Jungle"
    },
    {
      "x": -115,
      "y": 33,
      "z": 42,
      "name": "Cloth_Block_Wool_Gray_Light"
    },
    {
      "x": -115,
      "y": 33,
      "z": 43,
      "name": "Cloth_Block_Wool_Gray_Light"
    },
    {
      "x": -115,
      "y": 33,
      "z": 44,
      "name": "Cloth_Block_Wool_Gray_Light"
    },
    {
      "x": -115,
      "y": 33,
      "z": 45,
      "name": "Cloth_Block_Wool_Gray_Light"
    },
    {
      "x": -115,
      "y": 33,
      "z": 46,
      "name": "Cloth_Block_Wool_Gray_Light"
    },
    {
      "x": -115,
      "y": 33,
      "z": 47,
      "name": "Cloth_Block_Wool_Gray_Light"
    },
    {
      "x": -115,
      "y": 33,
      "z": 48,
      "name": "Cloth_Block_Wool_Gray_Light"
    },
    {
      "x": -115,
      "y": 33,
      "z": 49,
      "name": "Cloth_Block_Wool_Gray_Light"
    },
    {
      "x": -115,
      "y": 33,
      "z": 50,
      "name": "Cloth_Block_Wool_Gray_Light"
    },
    {
      "x": -115,
      "y": 33,
      "z": 51,
      "name": "Cloth_Block_Wool_Gray_Light"
    },
    {
      "x": -115,
      "y": 33,
      "z": 52,
      "name": "Cloth_Block_Wool_Gray_Light"
    },
    {
      "x": -115,
      "y": 33,
      "z": 53,
      "name": "Cloth_Block_Wool_Gray_Light"
    },
    {
      "x": -115,
      "y": 33,
      "z": 54,
      "name": "Cloth_Block_Wool_Gray_Light"
    },
    {
      "x": -115,
      "y": 33,
      "z": 55,
      "name": "Cloth_Block_Wool_Gray_Light"
    },
    {
      "x": -115,
      "y": 33,
      "z": 56,
      "name": "Cloth_Block_Wool_Gray_Light"
    },
    {
      "x": -115,
      "y": 33,
      "z": 57,
      "name": "Cloth_Block_Wool_Gray_Light"
    },
    {
      "x": -115,
      "y": 33,
      "z": 58,
      "name": "Cloth_Block_Wool_Gray_Light"
    },
    {
      "x": -115,
      "y": 33,
      "z": 59,
      "name": "Cloth_Block_Wool_Gray_Light"
    },
    {
      "x": -115,
      "y": 33,
      "z": 60,
      "name": "Cloth_Block_Wool_Gray_Light"
    },
    {
      "x": -115,
      "y": 33,
      "z": 61,
      "name": "Cloth_Block_Wool_Gray_Light"
    },
    {
      "x": -115,
      "y": 33,
      "z": 62,
      "name": "Cloth_Block_Wool_Gray_Light"
    },
    {
      "x": -115,
      "y": 33,
      "z": 63,
      "name": "Cloth_Block_Wool_Gray_Light"
    },
    {
      "x": -115,
      "y": 33,
      "z": 64,
      "name": "Cloth_Block_Wool_Gray_Light"
    },
    {
      "x": -115,
      "y": 33,
      "z": 65,
      "name": "Cloth_Block_Wool_Gray_Light"
    },
    {
      "x": -115,
      "y": 33,
      "z": 66,
      "name": "Cloth_Block_Wool_Gray_Light"
    },
    {
      "x": -115,
      "y": 33,
      "z": 67,
      "name": "Cloth_Block_Wool_Gray_Light"
    },
    {
      "x": -115,
      "y": 33,
      "z": 68,
      "name": "Cloth_Block_Wool_Gray_Light"
    },
    {
      "x": -115,
      "y": 33,
      "z": 69,
      "name": "Cloth_Block_Wool_Gray_Light"
    },
    {
      "x": -115,
      "y": 33,
      "z": 70,
      "name": "Cloth_Block_Wool_Gray_Light"
    },
    {
      "x": -115,
      "y": 33,
      "z": 71,
      "name": "Cloth_Block_Wool_Gray_Light"
    },
    {
      "x": -115,
      "y": 33,
      "z": 72,
      "name": "Cloth_Block_Wool_Gray_Light"
    },
    {
      "x": -115,
      "y": 33,
      "z": 73,
      "name": "Cloth_Block_Wool_Gray_Light"
    },
    {
      "x": -115,
      "y": 33,
      "z": 74,
      "name": "Cloth_Block_Wool_Gray_Light"
    },
    {
      "x": -115,
      "y": 33,
      "z": 75,
      "name": "Cloth_Block_Wool_Gray_Light"
    },
    {
      "x": -115,
      "y": 33,
      "z": 76,
      "name": "Cloth_Block_Wool_Gray_Light"
    },
    {
      "x": -115,
      "y": 33,
      "z": 77,
      "name": "Cloth_Block_Wool_Gray_Light"
    },
    {
      "x": -115,
      "y": 33,
      "z": 78,
      "name": "Cloth_Block_Wool_Gray_Light"
    },
    {
      "x": -115,
      "y": 33,
      "z": 79,
      "name": "Cloth_Block_Wool_Gray_Light"
    },
    {
      "x": -115,
      "y": 33,
      "z": 80,
      "name": "Cloth_Block_Wool_Gray_Light"
    },
    {
      "x": -115,
      "y": 33,
      "z": 81,
      "name": "Cloth_Block_Wool_Gray_Light"
    },
    {
      "x": -115,
      "y": 33,
      "z": 82,
      "name": "Cloth_Block_Wool_Gray_Light"
    },
    {
      "x": -115,
      "y": 33,
      "z": 83,
      "name": "Cloth_Block_Wool_Gray_Light"
    },
    {
      "x": -115,
      "y": 33,
      "z": 84,
      "name": "Cloth_Block_Wool_Gray_Light"
    },
    {
      "x": -115,
      "y": 33,
      "z": 85,
      "name": "Cloth_Block_Wool_Gray_Light"
    },
    {
      "x": -114,
      "y": 33,
      "z": -84,
      "name": "Cloth_Block_Wool_Gray_Light"
    },
    {
      "x": -114,
      "y": 33,
      "z": -83,
      "name": "Cloth_Block_Wool_Gray_Light"
    },
    {
      "x": -114,
      "y": 33,
      "z": -82,
      "name": "Cloth_Block_Wool_Gray_Light"
    },
    {
      "x": -114,
      "y": 33,
      "z": -81,
      "name": "Cloth_Block_Wool_Gray_Light"
    },
    {
      "x": -114,
      "y": 33,
      "z": -80,
      "name": "Cloth_Block_Wool_Gray_Light"
    },
    {
      "x": -114,
      "y": 33,
      "z": -79,
      "name": "Cloth_Block_Wool_Gray_Light"
    },
    {
      "x": -114,
      "y": 33,
      "z": -78,
      "name": "Cloth_Block_Wool_Gray_Light"
    },
    {
      "x": -114,
      "y": 33,
      "z": -77,
      "name": "Cloth_Block_Wool_Gray_Light"
    },
    {
      "x": -114,
      "y": 33,
      "z": -76,
      "name": "Cloth_Block_Wool_Gray_Light"
    },
    {
      "x": -114,
      "y": 33,
      "z": -75,
      "name": "Cloth_Block_Wool_Gray_Light"
    },
    {
      "x": -114,
      "y": 33,
      "z": -74,
      "name": "Cloth_Block_Wool_Gray_Light"
    },
    {
      "x": -114,
      "y": 33,
      "z": -73,
      "name": "Cloth_Block_Wool_Gray_Light"
    },
    {
      "x": -114,
      "y": 33,
      "z": -72,
      "name": "Cloth_Block_Wool_Gray_Light"
    },
    {
      "x": -114,
      "y": 33,
      "z": -71,
      "name": "Cloth_Block_Wool_Gray_Light"
    },
    {
      "x": -114,
      "y": 33,
      "z": -70,
      "name": "Cloth_Block_Wool_Gray_Light"
    },
    {
      "x": -114,
      "y": 33,
      "z": -69,
      "name": "Cloth_Block_Wool_Gray_Light"
    },
    {
      "x": -114,
      "y": 33,
      "z": -68,
      "name": "Cloth_Block_Wool_Gray_Light"
    },
    {
      "x": -114,
      "y": 33,
      "z": -67,
      "name": "Cloth_Block_Wool_Gray_Light"
    },
    {
      "x": -114,
      "y": 33,
      "z": -66,
      "name": "Cloth_Block_Wool_Gray_Light"
    },
    {
      "x": -114,
      "y": 33,
      "z": -65,
      "name": "Cloth_Block_Wool_Gray_Light"
    },
    {
      "x": -114,
      "y": 33,
      "z": -64,
      "name": "Cloth_Block_Wool_Gray_Light"
    },
    {
      "x": -114,
      "y": 33,
      "z": -63,
      "name": "Cloth_Block_Wool_Gray_Light"
    },
    {
      "x": -114,
      "y": 33,
      "z": -62,
      "name": "Cloth_Block_Wool_Gray_Light"
    },
    {
      "x": -114,
      "y": 33,
      "z": -61,
      "name": "Cloth_Block_Wool_Gray_Light"
    },
    {
      "x": -114,
      "y": 33,
      "z": -60,
      "name": "Cloth_Block_Wool_Gray_Light"
    },
    {
      "x": -114,
      "y": 33,
      "z": -59,
      "name": "Cloth_Block_Wool_Gray_Light"
    },
    {
      "x": -114,
      "y": 33,
      "z": -58,
      "name": "Cloth_Block_Wool_Gray_Light"
    },
    {
      "x": -114,
      "y": 33,
      "z": -57,
      "name": "Cloth_Block_Wool_Gray_Light"
    },
    {
      "x": -114,
      "y": 33,
      "z": -56,
      "name": "Cloth_Block_Wool_Gray_Light"
    },
    {
      "x": -114,
      "y": 33,
      "z": -55,
      "name": "Cloth_Block_Wool_Gray_Light"
    },
    {
      "x": -114,
      "y": 33,
      "z": -54,
      "name": "Cloth_Block_Wool_Gray_Light"
    },
    {
      "x": -114,
      "y": 33,
      "z": -53,
      "name": "Cloth_Block_Wool_Gray_Light"
    },
    {
      "x": -114,
      "y": 33,
      "z": -52,
      "name": "Cloth_Block_Wool_Gray_Light"
    },
    {
      "x": -114,
      "y": 33,
      "z": -51,
      "name": "Cloth_Block_Wool_Gray_Light"
    },
    {
      "x": -114,
      "y": 33,
      "z": -50,
      "name": "Cloth_Block_Wool_Gray_Light"
    },
    {
      "x": -114,
      "y": 33,
      "z": -49,
      "name": "Cloth_Block_Wool_Gray_Light"
    },
    {
      "x": -114,
      "y": 33,
      "z": -48,
      "name": "Cloth_Block_Wool_Gray_Light"
    },
    {
      "x": -114,
      "y": 33,
      "z": -47,
      "name": "Cloth_Block_Wool_Gray_Light"
    },
    {
      "x": -114,
      "y": 33,
      "z": -46,
      "name": "Cloth_Block_Wool_Gray_Light"
    },
    {
      "x": -114,
      "y": 33,
      "z": -45,
      "name": "Cloth_Block_Wool_Gray_Light"
    },
    {
      "x": -114,
      "y": 33,
      "z": -44,
      "name": "Cloth_Block_Wool_Gray_Light"
    },
    {
      "x": -114,
      "y": 33,
      "z": -43,
      "name": "Cloth_Block_Wool_Gray_Light"
    },
    {
      "x": -114,
      "y": 33,
      "z": -42,
      "name": "Cloth_Block_Wool_Gray_Light"
    },
    {
      "x": -114,
      "y": 33,
      "z": -41,
      "name": "Cloth_Block_Wool_Gray_Light"
    },
    {
      "x": -114,
      "y": 33,
      "z": -40,
      "name": "Cloth_Block_Wool_Gray_Light"
    },
    {
      "x": -114,
      "y": 33,
      "z": -39,
      "name": "Cloth_Block_Wool_Gray_Light"
    },
    {
      "x": -114,
      "y": 33,
      "z": -38,
      "name": "Cloth_Block_Wool_Gray_Light"
    },
    {
      "x": -114,
      "y": 33,
      "z": -37,
      "name": "Cloth_Block_Wool_Gray_Light"
    },
    {
      "x": -114,
      "y": 33,
      "z": -36,
      "name": "Cloth_Block_Wool_Gray_Light"
    },
    {
      "x": -114,
      "y": 33,
      "z": -35,
      "name": "Cloth_Block_Wool_Gray_Light"
    },
    {
      "x": -114,
      "y": 33,
      "z": -34,
      "name": "Cloth_Block_Wool_Gray_Light"
    },
    {
      "x": -114,
      "y": 33,
      "z": -33,
      "name": "Cloth_Block_Wool_Gray_Light"
    },
    {
      "x": -114,
      "y": 33,
      "z": -32,
      "name": "Cloth_Block_Wool_Gray_Light"
    },
    {
      "x": -114,
      "y": 33,
      "z": -31,
      "name": "Cloth_Block_Wool_Gray_Light"
    },
    {
      "x": -114,
      "y": 33,
      "z": -30,
      "name": "Cloth_Block_Wool_Gray_Light"
    },
    {
      "x": -114,
      "y": 33,
      "z": -29,
      "name": "Cloth_Block_Wool_Gray_Light"
    },
    {
      "x": -114,
      "y": 33,
      "z": -28,
      "name": "Cloth_Block_Wool_Gray_Light"
    },
    {
      "x": -114,
      "y": 33,
      "z": -27,
      "name": "Cloth_Block_Wool_Gray_Light"
    },
    {
      "x": -114,
      "y": 33,
      "z": -26,
      "name": "Cloth_Block_Wool_Gray_Light"
    },
    {
      "x": -114,
      "y": 33,
      "z": -25,
      "name": "Cloth_Block_Wool_Gray_Light"
    },
    {
      "x": -114,
      "y": 33,
      "z": -24,
      "name": "Cloth_Block_Wool_Gray_Light"
    },
    {
      "x": -114,
      "y": 33,
      "z": -23,
      "name": "Cloth_Block_Wool_Gray_Light"
    },
    {
      "x": -114,
      "y": 33,
      "z": -22,
      "name": "Cloth_Block_Wool_Gray_Light"
    },
    {
      "x": -114,
      "y": 33,
      "z": -21,
      "name": "Cloth_Block_Wool_Gray_Light"
    },
    {
      "x": -114,
      "y": 33,
      "z": -20,
      "name": "Cloth_Block_Wool_Gray_Light"
    },
    {
      "x": -114,
      "y": 33,
      "z": -19,
      "name": "Cloth_Block_Wool_Gray_Light"
    },
    {
      "x": -114,
      "y": 33,
      "z": -18,
      "name": "Cloth_Block_Wool_Gray_Light"
    },
    {
      "x": -114,
      "y": 33,
      "z": -17,
      "name": "Cloth_Block_Wool_Gray_Light"
    },
    {
      "x": -114,
      "y": 33,
      "z": -16,
      "name": "Cloth_Block_Wool_Gray_Light"
    },
    {
      "x": -114,
      "y": 33,
      "z": -15,
      "name": "Cloth_Block_Wool_Gray_Light"
    },
    {
      "x": -114,
      "y": 33,
      "z": -14,
      "name": "Cloth_Block_Wool_Gray_Light"
    },
    {
      "x": -114,
      "y": 33,
      "z": -13,
      "name": "Cloth_Block_Wool_Gray_Light"
    },
    {
      "x": -114,
      "y": 33,
      "z": -12,
      "name": "Cloth_Block_Wool_Gray_Light"
    },
    {
      "x": -114,
      "y": 33,
      "z": -11,
      "name": "Cloth_Block_Wool_Gray_Light"
    },
    {
      "x": -114,
      "y": 33,
      "z": -10,
      "name": "Cloth_Block_Wool_Gray_Light"
    },
    {
      "x": -114,
      "y": 33,
      "z": -9,
      "name": "Cloth_Block_Wool_Gray_Light"
    },
    {
      "x": -114,
      "y": 33,
      "z": -8,
      "name": "Cloth_Block_Wool_Gray_Light"
    },
    {
      "x": -114,
      "y": 33,
      "z": -7,
      "name": "Cloth_Block_Wool_Gray_Light"
    },
    {
      "x": -114,
      "y": 33,
      "z": -6,
      "name": "Cloth_Block_Wool_Gray_Light"
    },
    {
      "x": -114,
      "y": 33,
      "z": -5,
      "name": "Cloth_Block_Wool_Gray_Light"
    },
    {
      "x": -114,
      "y": 33,
      "z": -4,
      "name": "Cloth_Block_Wool_Gray_Light"
    },
    {
      "x": -114,
      "y": 33,
      "z": -3,
      "name": "Cloth_Block_Wool_Gray_Light"
    },
    {
      "x": -114,
      "y": 33,
      "z": -2,
      "name": "Cloth_Block_Wool_Gray_Light"
    },
    {
      "x": -114,
      "y": 33,
      "z": -1,
      "name": "Cloth_Block_Wool_Gray_Light"
    },
    {
      "x": -114,
      "y": 33,
      "z": 0,
      "name": "Cloth_Block_Wool_Gray_Light"
    },
    {
      "x": -114,
      "y": 33,
      "z": 1,
      "name": "Cloth_Block_Wool_Gray_Light"
    },
    {
      "x": -114,
      "y": 33,
      "z": 2,
      "name": "Cloth_Block_Wool_Gray_Light"
    },
    {
      "x": -114,
      "y": 33,
      "z": 3,
      "name": "Cloth_Block_Wool_Gray_Light"
    },
    {
      "x": -114,
      "y": 33,
      "z": 4,
      "name": "Cloth_Block_Wool_Gray_Light"
    },
    {
      "x": -114,
      "y": 33,
      "z": 5,
      "name": "Cloth_Block_Wool_Gray_Light"
    },
    {
      "x": -114,
      "y": 33,
      "z": 6,
      "name": "Cloth_Block_Wool_Gray_Light"
    },
    {
      "x": -114,
      "y": 33,
      "z": 7,
      "name": "Cloth_Block_Wool_Gray_Light"
    },
    {
      "x": -114,
      "y": 33,
      "z": 8,
      "name": "Cloth_Block_Wool_Gray_Light"
    },
    {
      "x": -114,
      "y": 33,
      "z": 9,
      "name": "Cloth_Block_Wool_Gray_Light"
    },
    {
      "x": -114,
      "y": 33,
      "z": 10,
      "name": "Cloth_Block_Wool_Gray_Light"
    },
    {
      "x": -114,
      "y": 33,
      "z": 11,
      "name": "Cloth_Block_Wool_Gray_Light"
    },
    {
      "x": -114,
      "y": 33,
      "z": 12,
      "name": "Cloth_Block_Wool_Gray_Light"
    },
    {
      "x": -114,
      "y": 33,
      "z": 13,
      "name": "Cloth_Block_Wool_Gray_Light"
    },
    {
      "x": -114,
      "y": 33,
      "z": 14,
      "name": "Cloth_Block_Wool_Gray_Light"
    },
    {
      "x": -114,
      "y": 33,
      "z": 15,
      "name": "Cloth_Block_Wool_Gray_Light"
    },
    {
      "x": -114,
      "y": 33,
      "z": 16,
      "name": "Cloth_Block_Wool_Gray_Light"
    },
    {
      "x": -114,
      "y": 33,
      "z": 17,
      "name": "Cloth_Block_Wool_Gray_Light"
    },
    {
      "x": -114,
      "y": 33,
      "z": 18,
      "name": "Cloth_Block_Wool_Gray_Light"
    },
    {
      "x": -114,
      "y": 33,
      "z": 19,
      "name": "Cloth_Block_Wool_Gray_Light"
    },
    {
      "x": -114,
      "y": 33,
      "z": 20,
      "name": "Cloth_Block_Wool_Gray_Light"
    },
    {
      "x": -114,
      "y": 33,
      "z": 21,
      "name": "Cloth_Block_Wool_Gray_Light"
    },
    {
      "x": -114,
      "y": 33,
      "z": 22,
      "name": "Cloth_Block_Wool_Gray_Light"
    },
    {
      "x": -114,
      "y": 33,
      "z": 23,
      "name": "Cloth_Block_Wool_Gray_Light"
    },
    {
      "x": -114,
      "y": 33,
      "z": 24,
      "name": "Cloth_Block_Wool_Gray_Light"
    },
    {
      "x": -114,
      "y": 33,
      "z": 25,
      "name": "Cloth_Block_Wool_Gray_Light"
    },
    {
      "x": -114,
      "y": 33,
      "z": 26,
      "name": "Cloth_Block_Wool_Gray_Light"
    },
    {
      "x": -114,
      "y": 33,
      "z": 27,
      "name": "Cloth_Block_Wool_Gray_Light"
    },
    {
      "x": -114,
      "y": 33,
      "z": 28,
      "name": "Cloth_Block_Wool_Gray_Light"
    },
    {
      "x": -114,
      "y": 33,
      "z": 29,
      "name": "Cloth_Block_Wool_Gray_Light"
    },
    {
      "x": -114,
      "y": 33,
      "z": 30,
      "name": "Cloth_Block_Wool_Gray_Light"
    },
    {
      "x": -114,
      "y": 33,
      "z": 31,
      "name": "Cloth_Block_Wool_Gray_Light"
    },
    {
      "x": -114,
      "y": 33,
      "z": 32,
      "name": "Cloth_Block_Wool_Gray_Light"
    },
    {
      "x": -114,
      "y": 33,
      "z": 33,
      "name": "Cloth_Block_Wool_Gray_Light"
    },
    {
      "x": -114,
      "y": 33,
      "z": 34,
      "name": "Cloth_Block_Wool_Gray_Light"
    },
    {
      "x": -114,
      "y": 33,
      "z": 35,
      "name": "Cloth_Block_Wool_Gray_Light"
    },
    {
      "x": -114,
      "y": 40,
      "z": 35,
      "name": "Plant_Leaves_Jungle"
    },
    {
      "x": -114,
      "y": 33,
      "z": 36,
      "name": "Cloth_Block_Wool_Gray_Light"
    },
    {
      "x": -114,
      "y": 40,
      "z": 36,
      "name": "Plant_Leaves_Jungle"
    },
    {
      "x": -114,
      "y": 33,
      "z": 37,
      "name": "Cloth_Block_Wool_Gray_Light"
    },
    {
      "x": -114,
      "y": 40,
      "z": 37,
      "name": "Wood_Jungle_Trunk_Full"
    },
    {
      "x": -114,
      "y": 41,
      "z": 37,
      "name": "Plant_Leaves_Jungle"
    },
    {
      "x": -114,
      "y": 33,
      "z": 38,
      "name": "Cloth_Block_Wool_Gray_Light"
    },
    {
      "x": -114,
      "y": 39,
      "z": 38,
      "name": "Wood_Jungle_Trunk_Full"
    },
    {
      "x": -114,
      "y": 40,
      "z": 38,
      "name": "Wood_Jungle_Trunk_Full"
    },
    {
      "x": -114,
      "y": 41,
      "z": 38,
      "name": "Plant_Leaves_Jungle"
    },
    {
      "x": -114,
      "y": 33,
      "z": 39,
      "name": "Cloth_Block_Wool_Gray_Light"
    },
    {
      "x": -114,
      "y": 39,
      "z": 39,
      "name": "Wood_Jungle_Trunk_Full"
    },
    {
      "x": -114,
      "y": 40,
      "z": 39,
      "name": "Plant_Leaves_Jungle"
    },
    {
      "x": -114,
      "y": 41,
      "z": 39,
      "name": "Plant_Leaves_Jungle"
    },
    {
      "x": -114,
      "y": 33,
      "z": 40,
      "name": "Cloth_Block_Wool_Gray_Light"
    },
    {
      "x": -114,
      "y": 38,
      "z": 40,
      "name": "Plant_Leaves_Jungle"
    },
    {
      "x": -114,
      "y": 39,
      "z": 40,
      "name": "Plant_Leaves_Jungle"
    },
    {
      "x": -114,
      "y": 33,
      "z": 41,
      "name": "Cloth_Block_Wool_Gray_Light"
    },
    {
      "x": -114,
      "y": 38,
      "z": 41,
      "name": "Plant_Leaves_Jungle"
    },
    {
      "x": -114,
      "y": 33,
      "z": 42,
      "name": "Cloth_Block_Wool_Gray_Light"
    },
    {
      "x": -114,
      "y": 38,
      "z": 42,
      "name": "Plant_Leaves_Jungle"
    },
    {
      "x": -114,
      "y": 33,
      "z": 43,
      "name": "Cloth_Block_Wool_Gray_Light"
    },
    {
      "x": -114,
      "y": 33,
      "z": 44,
      "name": "Cloth_Block_Wool_Gray_Light"
    },
    {
      "x": -114,
      "y": 33,
      "z": 45,
      "name": "Cloth_Block_Wool_Gray_Light"
    },
    {
      "x": -114,
      "y": 33,
      "z": 46,
      "name": "Cloth_Block_Wool_Gray_Light"
    },
    {
      "x": -114,
      "y": 33,
      "z": 47,
      "name": "Cloth_Block_Wool_Gray_Light"
    },
    {
      "x": -114,
      "y": 33,
      "z": 48,
      "name": "Cloth_Block_Wool_Gray_Light"
    },
    {
      "x": -114,
      "y": 33,
      "z": 49,
      "name": "Cloth_Block_Wool_Gray_Light"
    },
    {
      "x": -114,
      "y": 33,
      "z": 50,
      "name": "Cloth_Block_Wool_Gray_Light"
    },
    {
      "x": -114,
      "y": 33,
      "z": 51,
      "name": "Cloth_Block_Wool_Gray_Light"
    },
    {
      "x": -114,
      "y": 33,
      "z": 52,
      "name": "Cloth_Block_Wool_Gray_Light"
    },
    {
      "x": -114,
      "y": 33,
      "z": 53,
      "name": "Cloth_Block_Wool_Gray_Light"
    },
    {
      "x": -114,
      "y": 33,
      "z": 54,
      "name": "Cloth_Block_Wool_Gray_Light"
    },
    {
      "x": -114,
      "y": 33,
      "z": 55,
      "name": "Cloth_Block_Wool_Gray_Light"
    },
    {
      "x": -114,
      "y": 33,
      "z": 56,
      "name": "Cloth_Block_Wool_Gray_Light"
    },
    {
      "x": -114,
      "y": 33,
      "z": 57,
      "name": "Cloth_Block_Wool_Gray_Light"
    },
    {
      "x": -114,
      "y": 33,
      "z": 58,
      "name": "Cloth_Block_Wool_Gray_Light"
    },
    {
      "x": -114,
      "y": 33,
      "z": 59,
      "name": "Cloth_Block_Wool_Gray_Light"
    },
    {
      "x": -114,
      "y": 33,
      "z": 60,
      "name": "Cloth_Block_Wool_Gray_Light"
    },
    {
      "x": -114,
      "y": 33,
      "z": 61,
      "name": "Cloth_Block_Wool_Gray_Light"
    },
    {
      "x": -114,
      "y": 33,
      "z": 62,
      "name": "Cloth_Block_Wool_Gray_Light"
    },
    {
      "x": -114,
      "y": 33,
      "z": 63,
      "name": "Cloth_Block_Wool_Gray_Light"
    },
    {
      "x": -114,
      "y": 33,
      "z": 64,
      "name": "Cloth_Block_Wool_Gray_Light"
    },
    {
      "x": -114,
      "y": 33,
      "z": 65,
      "name": "Cloth_Block_Wool_Gray_Light"
    },
    {
      "x": -114,
      "y": 33,
      "z": 66,
      "name": "Cloth_Block_Wool_Gray_Light"
    },
    {
      "x": -114,
      "y": 34,
      "z": 66,
      "name": "Plant_Coral_Block_Yellow"
    },
    {
      "x": -114,
      "y": 35,
      "z": 66,
      "name": "Plant_Coral_Block_Yellow"
    },
    {
      "x": -114,
      "y": 33,
      "z": 67,
      "name": "Cloth_Block_Wool_Gray_Light"
    },
    {
      "x": -114,
      "y": 34,
      "z": 67,
      "name": "Plant_Coral_Block_Yellow"
    },
    {
      "x": -114,
      "y": 35,
      "z": 67,
      "name": "Plant_Coral_Block_Yellow"
    },
    {
      "x": -114,
      "y": 36,
      "z": 67,
      "name": "Plant_Coral_Block_Yellow"
    },
    {
      "x": -114,
      "y": 33,
      "z": 68,
      "name": "Cloth_Block_Wool_Gray_Light"
    },
    {
      "x": -114,
      "y": 33,
      "z": 69,
      "name": "Cloth_Block_Wool_Gray_Light"
    },
    {
      "x": -114,
      "y": 33,
      "z": 70,
      "name": "Cloth_Block_Wool_Gray_Light"
    },
    {
      "x": -114,
      "y": 33,
      "z": 71,
      "name": "Cloth_Block_Wool_Gray_Light"
    },
    {
      "x": -114,
      "y": 33,
      "z": 72,
      "name": "Cloth_Block_Wool_Gray_Light"
    },
    {
      "x": -114,
      "y": 33,
      "z": 73,
      "name": "Cloth_Block_Wool_Gray_Light"
    },
    {
      "x": -114,
      "y": 34,
      "z": 73,
      "name": "Plant_Coral_Block_Lime"
    },
    {
      "x": -114,
      "y": 35,
      "z": 73,
      "name": "Plant_Coral_Block_Lime"
    },
    {
      "x": -114,
      "y": 36,
      "z": 73,
      "name": "Plant_Coral_Block_Lime"
    },
    {
      "x": -114,
      "y": 33,
      "z": 74,
      "name": "Cloth_Block_Wool_Gray_Light"
    },
    {
      "x": -114,
      "y": 34,
      "z": 74,
      "name": "Plant_Coral_Block_Lime"
    },
    {
      "x": -114,
      "y": 35,
      "z": 74,
      "name": "Plant_Coral_Block_Lime"
    },
    {
      "x": -114,
      "y": 36,
      "z": 74,
      "name": "Plant_Coral_Block_Lime"
    },
    {
      "x": -114,
      "y": 33,
      "z": 75,
      "name": "Cloth_Block_Wool_Gray_Light"
    },
    {
      "x": -114,
      "y": 34,
      "z": 75,
      "name": "Plant_Coral_Block_Lime"
    },
    {
      "x": -114,
      "y": 35,
      "z": 75,
      "name": "Plant_Coral_Block_Lime"
    },
    {
      "x": -114,
      "y": 36,
      "z": 75,
      "name": "Plant_Coral_Block_Lime"
    },
    {
      "x": -114,
      "y": 33,
      "z": 76,
      "name": "Cloth_Block_Wool_Gray_Light"
    },
    {
      "x": -114,
      "y": 34,
      "z": 76,
      "name": "Plant_Coral_Block_Lime"
    },
    {
      "x": -114,
      "y": 35,
      "z": 76,
      "name": "Plant_Coral_Block_Lime"
    },
    {
      "x": -114,
      "y": 33,
      "z": 77,
      "name": "Cloth_Block_Wool_Gray_Light"
    },
    {
      "x": -114,
      "y": 33,
      "z": 78,
      "name": "Cloth_Block_Wool_Gray_Light"
    },
    {
      "x": -114,
      "y": 33,
      "z": 79,
      "name": "Cloth_Block_Wool_Gray_Light"
    },
    {
      "x": -114,
      "y": 33,
      "z": 80,
      "name": "Cloth_Block_Wool_Gray_Light"
    },
    {
      "x": -114,
      "y": 33,
      "z": 81,
      "name": "Cloth_Block_Wool_Gray_Light"
    },
    {
      "x": -114,
      "y": 34,
      "z": 81,
      "name": "Plant_Coral_Block_Purple"
    },
    {
      "x": -114,
      "y": 35,
      "z": 81,
      "name": "Plant_Coral_Block_Purple"
    },
    {
      "x": -114,
      "y": 36,
      "z": 81,
      "name": "Plant_Coral_Block_Purple"
    },
    {
      "x": -114,
      "y": 33,
      "z": 82,
      "name": "Cloth_Block_Wool_Gray_Light"
    },
    {
      "x": -114,
      "y": 34,
      "z": 82,
      "name": "Plant_Coral_Block_Purple"
    },
    {
      "x": -114,
      "y": 35,
      "z": 82,
      "name": "Plant_Coral_Block_Purple"
    },
    {
      "x": -114,
      "y": 36,
      "z": 82,
      "name": "Plant_Coral_Block_Purple"
    },
    {
      "x": -114,
      "y": 33,
      "z": 83,
      "name": "Cloth_Block_Wool_Gray_Light"
    },
    {
      "x": -114,
      "y": 34,
      "z": 83,
      "name": "Plant_Coral_Block_Purple"
    },
    {
      "x": -114,
      "y": 35,
      "z": 83,
      "name": "Plant_Coral_Block_Purple"
    },
    {
      "x": -114,
      "y": 36,
      "z": 83,
      "name": "Plant_Coral_Block_Purple"
    },
    {
      "x": -114,
      "y": 33,
      "z": 84,
      "name": "Cloth_Block_Wool_Gray_Light"
    },
    {
      "x": -114,
      "y": 33,
      "z": 85,
      "name": "Cloth_Block_Wool_Gray_Light"
    },
    {
      "x": -113,
      "y": 33,
      "z": -84,
      "name": "Cloth_Block_Wool_Gray_Light"
    },
    {
      "x": -113,
      "y": 33,
      "z": -83,
      "name": "Cloth_Block_Wool_Gray_Light"
    },
    {
      "x": -113,
      "y": 33,
      "z": -82,
      "name": "Cloth_Block_Wool_Gray_Light"
    },
    {
      "x": -113,
      "y": 33,
      "z": -81,
      "name": "Cloth_Block_Wool_Gray_Light"
    },
    {
      "x": -113,
      "y": 33,
      "z": -80,
      "name": "Cloth_Block_Wool_Gray_Light"
    },
    {
      "x": -113,
      "y": 33,
      "z": -79,
      "name": "Cloth_Block_Wool_Gray_Light"
    },
    {
      "x": -113,
      "y": 33,
      "z": -78,
      "name": "Cloth_Block_Wool_Gray_Light"
    },
    {
      "x": -113,
      "y": 33,
      "z": -77,
      "name": "Cloth_Block_Wool_Gray_Light"
    },
    {
      "x": -113,
      "y": 33,
      "z": -76,
      "name": "Cloth_Block_Wool_Gray_Light"
    },
    {
      "x": -113,
      "y": 33,
      "z": -75,
      "name": "Cloth_Block_Wool_Gray_Light"
    },
    {
      "x": -113,
      "y": 33,
      "z": -74,
      "name": "Cloth_Block_Wool_Gray_Light"
    },
    {
      "x": -113,
      "y": 33,
      "z": -73,
      "name": "Cloth_Block_Wool_Gray_Light"
    },
    {
      "x": -113,
      "y": 33,
      "z": -72,
      "name": "Cloth_Block_Wool_Gray_Light"
    },
    {
      "x": -113,
      "y": 33,
      "z": -71,
      "name": "Cloth_Block_Wool_Gray_Light"
    },
    {
      "x": -113,
      "y": 33,
      "z": -70,
      "name": "Cloth_Block_Wool_Gray_Light"
    },
    {
      "x": -113,
      "y": 33,
      "z": -69,
      "name": "Cloth_Block_Wool_Gray_Light"
    },
    {
      "x": -113,
      "y": 33,
      "z": -68,
      "name": "Cloth_Block_Wool_Gray_Light"
    },
    {
      "x": -113,
      "y": 33,
      "z": -67,
      "name": "Cloth_Block_Wool_Gray_Light"
    },
    {
      "x": -113,
      "y": 33,
      "z": -66,
      "name": "Cloth_Block_Wool_Gray_Light"
    },
    {
      "x": -113,
      "y": 33,
      "z": -65,
      "name": "Cloth_Block_Wool_Gray_Light"
    },
    {
      "x": -113,
      "y": 33,
      "z": -64,
      "name": "Cloth_Block_Wool_Gray_Light"
    },
    {
      "x": -113,
      "y": 33,
      "z": -63,
      "name": "Cloth_Block_Wool_Gray_Light"
    },
    {
      "x": -113,
      "y": 33,
      "z": -62,
      "name": "Cloth_Block_Wool_Gray_Light"
    },
    {
      "x": -113,
      "y": 33,
      "z": -61,
      "name": "Cloth_Block_Wool_Gray_Light"
    },
    {
      "x": -113,
      "y": 33,
      "z": -60,
      "name": "Cloth_Block_Wool_Gray_Light"
    },
    {
      "x": -113,
      "y": 33,
      "z": -59,
      "name": "Cloth_Block_Wool_Gray_Light"
    },
    {
      "x": -113,
      "y": 33,
      "z": -58,
      "name": "Cloth_Block_Wool_Gray_Light"
    },
    {
      "x": -113,
      "y": 33,
      "z": -57,
      "name": "Cloth_Block_Wool_Gray_Light"
    },
    {
      "x": -113,
      "y": 33,
      "z": -56,
      "name": "Cloth_Block_Wool_Gray_Light"
    },
    {
      "x": -113,
      "y": 33,
      "z": -55,
      "name": "Cloth_Block_Wool_Gray_Light"
    },
    {
      "x": -113,
      "y": 33,
      "z": -54,
      "name": "Cloth_Block_Wool_Gray_Light"
    },
    {
      "x": -113,
      "y": 33,
      "z": -53,
      "name": "Cloth_Block_Wool_Gray_Light"
    },
    {
      "x": -113,
      "y": 33,
      "z": -52,
      "name": "Cloth_Block_Wool_Gray_Light"
    },
    {
      "x": -113,
      "y": 33,
      "z": -51,
      "name": "Cloth_Block_Wool_Gray_Light"
    },
    {
      "x": -113,
      "y": 33,
      "z": -50,
      "name": "Cloth_Block_Wool_Gray_Light"
    },
    {
      "x": -113,
      "y": 33,
      "z": -49,
      "name": "Cloth_Block_Wool_Gray_Light"
    },
    {
      "x": -113,
      "y": 33,
      "z": -48,
      "name": "Cloth_Block_Wool_Gray_Light"
    },
    {
      "x": -113,
      "y": 33,
      "z": -47,
      "name": "Cloth_Block_Wool_Gray_Light"
    },
    {
      "x": -113,
      "y": 33,
      "z": -46,
      "name": "Cloth_Block_Wool_Gray_Light"
    },
    {
      "x": -113,
      "y": 33,
      "z": -45,
      "name": "Cloth_Block_Wool_Gray_Light"
    },
    {
      "x": -113,
      "y": 33,
      "z": -44,
      "name": "Cloth_Block_Wool_Gray_Light"
    },
    {
      "x": -113,
      "y": 33,
      "z": -43,
      "name": "Cloth_Block_Wool_Gray_Light"
    },
    {
      "x": -113,
      "y": 33,
      "z": -42,
      "name": "Cloth_Block_Wool_Gray_Light"
    },
    {
      "x": -113,
      "y": 33,
      "z": -41,
      "name": "Cloth_Block_Wool_Gray_Light"
    },
    {
      "x": -113,
      "y": 33,
      "z": -40,
      "name": "Cloth_Block_Wool_Gray_Light"
    },
    {
      "x": -113,
      "y": 33,
      "z": -39,
      "name": "Cloth_Block_Wool_Gray_Light"
    },
    {
      "x": -113,
      "y": 33,
      "z": -38,
      "name": "Cloth_Block_Wool_Gray_Light"
    },
    {
      "x": -113,
      "y": 33,
      "z": -37,
      "name": "Cloth_Block_Wool_Gray_Light"
    },
    {
      "x": -113,
      "y": 33,
      "z": -36,
      "name": "Cloth_Block_Wool_Gray_Light"
    },
    {
      "x": -113,
      "y": 33,
      "z": -35,
      "name": "Cloth_Block_Wool_Gray_Light"
    },
    {
      "x": -113,
      "y": 33,
      "z": -34,
      "name": "Cloth_Block_Wool_Gray_Light"
    },
    {
      "x": -113,
      "y": 33,
      "z": -33,
      "name": "Cloth_Block_Wool_Gray_Light"
    },
    {
      "x": -113,
      "y": 33,
      "z": -32,
      "name": "Cloth_Block_Wool_Gray_Light"
    },
    {
      "x": -113,
      "y": 33,
      "z": -31,
      "name": "Cloth_Block_Wool_Gray_Light"
    },
    {
      "x": -113,
      "y": 33,
      "z": -30,
      "name": "Cloth_Block_Wool_Gray_Light"
    },
    {
      "x": -113,
      "y": 33,
      "z": -29,
      "name": "Cloth_Block_Wool_Gray_Light"
    },
    {
      "x": -113,
      "y": 33,
      "z": -28,
      "name": "Cloth_Block_Wool_Gray_Light"
    },
    {
      "x": -113,
      "y": 33,
      "z": -27,
      "name": "Cloth_Block_Wool_Gray_Light"
    },
    {
      "x": -113,
      "y": 33,
      "z": -26,
      "name": "Cloth_Block_Wool_Gray_Light"
    },
    {
      "x": -113,
      "y": 33,
      "z": -25,
      "name": "Cloth_Block_Wool_Gray_Light"
    },
    {
      "x": -113,
      "y": 33,
      "z": -24,
      "name": "Cloth_Block_Wool_Gray_Light"
    },
    {
      "x": -113,
      "y": 33,
      "z": -23,
      "name": "Cloth_Block_Wool_Gray_Light"
    },
    {
      "x": -113,
      "y": 33,
      "z": -22,
      "name": "Cloth_Block_Wool_Gray_Light"
    },
    {
      "x": -113,
      "y": 33,
      "z": -21,
      "name": "Cloth_Block_Wool_Gray_Light"
    },
    {
      "x": -113,
      "y": 33,
      "z": -20,
      "name": "Cloth_Block_Wool_Gray_Light"
    },
    {
      "x": -113,
      "y": 33,
      "z": -19,
      "name": "Cloth_Block_Wool_Gray_Light"
    },
    {
      "x": -113,
      "y": 33,
      "z": -18,
      "name": "Cloth_Block_Wool_Gray_Light"
    },
    {
      "x": -113,
      "y": 33,
      "z": -17,
      "name": "Cloth_Block_Wool_Gray_Light"
    },
    {
      "x": -113,
      "y": 33,
      "z": -16,
      "name": "Cloth_Block_Wool_Gray_Light"
    },
    {
      "x": -113,
      "y": 33,
      "z": -15,
      "name": "Cloth_Block_Wool_Gray_Light"
    },
    {
      "x": -113,
      "y": 33,
      "z": -14,
      "name": "Cloth_Block_Wool_Gray_Light"
    },
    {
      "x": -113,
      "y": 33,
      "z": -13,
      "name": "Cloth_Block_Wool_Gray_Light"
    },
    {
      "x": -113,
      "y": 33,
      "z": -12,
      "name": "Cloth_Block_Wool_Gray_Light"
    },
    {
      "x": -113,
      "y": 33,
      "z": -11,
      "name": "Cloth_Block_Wool_Gray_Light"
    },
    {
      "x": -113,
      "y": 33,
      "z": -10,
      "name": "Cloth_Block_Wool_Gray_Light"
    },
    {
      "x": -113,
      "y": 33,
      "z": -9,
      "name": "Cloth_Block_Wool_Gray_Light"
    },
    {
      "x": -113,
      "y": 33,
      "z": -8,
      "name": "Cloth_Block_Wool_Gray_Light"
    },
    {
      "x": -113,
      "y": 33,
      "z": -7,
      "name": "Cloth_Block_Wool_Gray_Light"
    },
    {
      "x": -113,
      "y": 33,
      "z": -6,
      "name": "Cloth_Block_Wool_Gray_Light"
    },
    {
      "x": -113,
      "y": 33,
      "z": -5,
      "name": "Cloth_Block_Wool_Gray_Light"
    },
    {
      "x": -113,
      "y": 33,
      "z": -4,
      "name": "Cloth_Block_Wool_Gray_Light"
    },
    {
      "x": -113,
      "y": 33,
      "z": -3,
      "name": "Cloth_Block_Wool_Gray_Light"
    },
    {
      "x": -113,
      "y": 33,
      "z": -2,
      "name": "Cloth_Block_Wool_Gray_Light"
    },
    {
      "x": -113,
      "y": 33,
      "z": -1,
      "name": "Cloth_Block_Wool_Gray_Light"
    },
    {
      "x": -113,
      "y": 33,
      "z": 0,
      "name": "Cloth_Block_Wool_Gray_Light"
    },
    {
      "x": -113,
      "y": 33,
      "z": 1,
      "name": "Cloth_Block_Wool_Gray_Light"
    },
    {
      "x": -113,
      "y": 33,
      "z": 2,
      "name": "Cloth_Block_Wool_Gray_Light"
    },
    {
      "x": -113,
      "y": 33,
      "z": 3,
      "name": "Cloth_Block_Wool_Gray_Light"
    },
    {
      "x": -113,
      "y": 33,
      "z": 4,
      "name": "Cloth_Block_Wool_Gray_Light"
    },
    {
      "x": -113,
      "y": 33,
      "z": 5,
      "name": "Cloth_Block_Wool_Gray_Light"
    },
    {
      "x": -113,
      "y": 33,
      "z": 6,
      "name": "Cloth_Block_Wool_Gray_Light"
    },
    {
      "x": -113,
      "y": 33,
      "z": 7,
      "name": "Cloth_Block_Wool_Gray_Light"
    },
    {
      "x": -113,
      "y": 33,
      "z": 8,
      "name": "Cloth_Block_Wool_Gray_Light"
    },
    {
      "x": -113,
      "y": 33,
      "z": 9,
      "name": "Cloth_Block_Wool_Gray_Light"
    },
    {
      "x": -113,
      "y": 33,
      "z": 10,
      "name": "Cloth_Block_Wool_Gray_Light"
    },
    {
      "x": -113,
      "y": 33,
      "z": 11,
      "name": "Cloth_Block_Wool_Gray_Light"
    },
    {
      "x": -113,
      "y": 33,
      "z": 12,
      "name": "Cloth_Block_Wool_Gray_Light"
    },
    {
      "x": -113,
      "y": 33,
      "z": 13,
      "name": "Cloth_Block_Wool_Gray_Light"
    },
    {
      "x": -113,
      "y": 33,
      "z": 14,
      "name": "Cloth_Block_Wool_Gray_Light"
    },
    {
      "x": -113,
      "y": 33,
      "z": 15,
      "name": "Cloth_Block_Wool_Gray_Light"
    },
    {
      "x": -113,
      "y": 33,
      "z": 16,
      "name": "Cloth_Block_Wool_Gray_Light"
    },
    {
      "x": -113,
      "y": 33,
      "z": 17,
      "name": "Cloth_Block_Wool_Gray_Light"
    },
    {
      "x": -113,
      "y": 33,
      "z": 18,
      "name": "Cloth_Block_Wool_Gray_Light"
    },
    {
      "x": -113,
      "y": 33,
      "z": 19,
      "name": "Cloth_Block_Wool_Gray_Light"
    },
    {
      "x": -113,
      "y": 33,
      "z": 20,
      "name": "Cloth_Block_Wool_Gray_Light"
    },
    {
      "x": -113,
      "y": 33,
      "z": 21,
      "name": "Cloth_Block_Wool_Gray_Light"
    },
    {
      "x": -113,
      "y": 33,
      "z": 22,
      "name": "Cloth_Block_Wool_Gray_Light"
    },
    {
      "x": -113,
      "y": 33,
      "z": 23,
      "name": "Cloth_Block_Wool_Gray_Light"
    },
    {
      "x": -113,
      "y": 33,
      "z": 24,
      "name": "Cloth_Block_Wool_Gray_Light"
    },
    {
      "x": -113,
      "y": 33,
      "z": 25,
      "name": "Cloth_Block_Wool_Gray_Light"
    },
    {
      "x": -113,
      "y": 33,
      "z": 26,
      "name": "Cloth_Block_Wool_Gray_Light"
    },
    {
      "x": -113,
      "y": 33,
      "z": 27,
      "name": "Cloth_Block_Wool_Gray_Light"
    },
    {
      "x": -113,
      "y": 32,
      "z": 28,
      "name": "Plant_Fern_Jungle_Trunk"
    },
    {
      "x": -113,
      "y": 33,
      "z": 28,
      "name": "Plant_Fern_Jungle_Trunk"
    },
    {
      "x": -113,
      "y": 34,
      "z": 28,
      "name": "Plant_Fern_Jungle_Trunk"
    },
    {
      "x": -113,
      "y": 35,
      "z": 28,
      "name": "Plant_Fern_Jungle_Trunk"
    },
    {
      "x": -113,
      "y": 36,
      "z": 28,
      "name": "Plant_Fern_Jungle_Trunk"
    },
    {
      "x": -113,
      "y": 37,
      "z": 28,
      "name": "Plant_Fern_Jungle_Trunk"
    },
    {
      "x": -113,
      "y": 38,
      "z": 28,
      "name": "Plant_Fern_Jungle"
    },
    {
      "x": -113,
      "y": 33,
      "z": 29,
      "name": "Cloth_Block_Wool_Gray_Light"
    },
    {
      "x": -113,
      "y": 33,
      "z": 30,
      "name": "Cloth_Block_Wool_Gray_Light"
    },
    {
      "x": -113,
      "y": 33,
      "z": 31,
      "name": "Cloth_Block_Wool_Gray_Light"
    },
    {
      "x": -113,
      "y": 33,
      "z": 32,
      "name": "Cloth_Block_Wool_Gray_Light"
    },
    {
      "x": -113,
      "y": 33,
      "z": 33,
      "name": "Cloth_Block_Wool_Gray_Light"
    },
    {
      "x": -113,
      "y": 33,
      "z": 34,
      "name": "Cloth_Block_Wool_Gray_Light"
    },
    {
      "x": -113,
      "y": 33,
      "z": 35,
      "name": "Cloth_Block_Wool_Gray_Light"
    },
    {
      "x": -113,
      "y": 33,
      "z": 36,
      "name": "Cloth_Block_Wool_Gray_Light"
    },
    {
      "x": -113,
      "y": 39,
      "z": 36,
      "name": "Plant_Leaves_Jungle"
    },
    {
      "x": -113,
      "y": 40,
      "z": 36,
      "name": "Plant_Leaves_Jungle"
    },
    {
      "x": -113,
      "y": 33,
      "z": 37,
      "name": "Cloth_Block_Wool_Gray_Light"
    },
    {
      "x": -113,
      "y": 39,
      "z": 37,
      "name": "Plant_Leaves_Jungle"
    },
    {
      "x": -113,
      "y": 40,
      "z": 37,
      "name": "Plant_Leaves_Jungle"
    },
    {
      "x": -113,
      "y": 33,
      "z": 38,
      "name": "Cloth_Block_Wool_Gray_Light"
    },
    {
      "x": -113,
      "y": 39,
      "z": 38,
      "name": "Plant_Leaves_Jungle"
    },
    {
      "x": -113,
      "y": 40,
      "z": 38,
      "name": "Plant_Leaves_Jungle"
    },
    {
      "x": -113,
      "y": 41,
      "z": 38,
      "name": "Plant_Leaves_Jungle"
    },
    {
      "x": -113,
      "y": 33,
      "z": 39,
      "name": "Cloth_Block_Wool_Gray_Light"
    },
    {
      "x": -113,
      "y": 37,
      "z": 39,
      "name": "Wood_Jungle_Trunk_Full"
    },
    {
      "x": -113,
      "y": 38,
      "z": 39,
      "name": "Wood_Jungle_Trunk"
    },
    {
      "x": -113,
      "y": 39,
      "z": 39,
      "name": "Wood_Jungle_Trunk"
    },
    {
      "x": -113,
      "y": 40,
      "z": 39,
      "name": "Plant_Leaves_Jungle"
    },
    {
      "x": -113,
      "y": 33,
      "z": 40,
      "name": "Cloth_Block_Wool_Gray_Light"
    },
    {
      "x": -113,
      "y": 37,
      "z": 40,
      "name": "Wood_Jungle_Trunk_Full"
    },
    {
      "x": -113,
      "y": 38,
      "z": 40,
      "name": "Plant_Leaves_Jungle"
    },
    {
      "x": -113,
      "y": 39,
      "z": 40,
      "name": "Plant_Leaves_Jungle"
    },
    {
      "x": -113,
      "y": 40,
      "z": 40,
      "name": "Plant_Leaves_Jungle"
    },
    {
      "x": -113,
      "y": 33,
      "z": 41,
      "name": "Cloth_Block_Wool_Gray_Light"
    },
    {
      "x": -113,
      "y": 37,
      "z": 41,
      "name": "Plant_Leaves_Jungle"
    },
    {
      "x": -113,
      "y": 38,
      "z": 41,
      "name": "Plant_Leaves_Jungle"
    },
    {
      "x": -113,
      "y": 33,
      "z": 42,
      "name": "Cloth_Block_Wool_Gray_Light"
    },
    {
      "x": -113,
      "y": 38,
      "z": 42,
      "name": "Plant_Leaves_Jungle"
    },
    {
      "x": -113,
      "y": 33,
      "z": 43,
      "name": "Cloth_Block_Wool_Gray_Light"
    },
    {
      "x": -113,
      "y": 33,
      "z": 44,
      "name": "Cloth_Block_Wool_Gray_Light"
    },
    {
      "x": -113,
      "y": 33,
      "z": 45,
      "name": "Cloth_Block_Wool_Gray_Light"
    },
    {
      "x": -113,
      "y": 33,
      "z": 46,
      "name": "Cloth_Block_Wool_Gray_Light"
    },
    {
      "x": -113,
      "y": 33,
      "z": 47,
      "name": "Cloth_Block_Wool_Gray_Light"
    },
    {
      "x": -113,
      "y": 33,
      "z": 48,
      "name": "Cloth_Block_Wool_Gray_Light"
    },
    {
      "x": -113,
      "y": 33,
      "z": 49,
      "name": "Cloth_Block_Wool_Gray_Light"
    },
    {
      "x": -113,
      "y": 34,
      "z": 49,
      "name": "Plant_Fern_Jungle_Trunk"
    },
    {
      "x": -113,
      "y": 35,
      "z": 49,
      "name": "Plant_Fern_Jungle_Trunk"
    },
    {
      "x": -113,
      "y": 36,
      "z": 49,
      "name": "Wood_Jungle_Branch_Long"
    },
    {
      "x": -113,
      "y": 37,
      "z": 49,
      "name": "Wood_Jungle_Branch_Long"
    },
    {
      "x": -113,
      "y": 38,
      "z": 49,
      "name": "Plant_Fern_Jungle"
    },
    {
      "x": -113,
      "y": 33,
      "z": 50,
      "name": "Cloth_Block_Wool_Gray_Light"
    },
    {
      "x": -113,
      "y": 33,
      "z": 51,
      "name": "Cloth_Block_Wool_Gray_Light"
    },
    {
      "x": -113,
      "y": 33,
      "z": 52,
      "name": "Cloth_Block_Wool_Gray_Light"
    },
    {
      "x": -113,
      "y": 33,
      "z": 53,
      "name": "Cloth_Block_Wool_Gray_Light"
    },
    {
      "x": -113,
      "y": 33,
      "z": 54,
      "name": "Cloth_Block_Wool_Gray_Light"
    },
    {
      "x": -113,
      "y": 33,
      "z": 55,
      "name": "Cloth_Block_Wool_Gray_Light"
    },
    {
      "x": -113,
      "y": 33,
      "z": 56,
      "name": "Cloth_Block_Wool_Gray_Light"
    },
    {
      "x": -113,
      "y": 33,
      "z": 57,
      "name": "Cloth_Block_Wool_Gray_Light"
    },
    {
      "x": -113,
      "y": 33,
      "z": 58,
      "name": "Cloth_Block_Wool_Gray_Light"
    },
    {
      "x": -113,
      "y": 33,
      "z": 59,
      "name": "Cloth_Block_Wool_Gray_Light"
    },
    {
      "x": -113,
      "y": 33,
      "z": 60,
      "name": "Cloth_Block_Wool_Gray_Light"
    },
    {
      "x": -113,
      "y": 34,
      "z": 60,
      "name": "Plant_Coral_Block_Cyan"
    },
    {
      "x": -113,
      "y": 35,
      "z": 60,
      "name": "Plant_Coral_Block_Cyan"
    },
    {
      "x": -113,
      "y": 36,
      "z": 60,
      "name": "Plant_Coral_Block_Cyan"
    },
    {
      "x": -113,
      "y": 33,
      "z": 61,
      "name": "Cloth_Block_Wool_Gray_Light"
    },
    {
      "x": -113,
      "y": 34,
      "z": 61,
      "name": "Plant_Coral_Block_Cyan"
    },
    {
      "x": -113,
      "y": 35,
      "z": 61,
      "name": "Plant_Coral_Block_Cyan"
    },
    {
      "x": -113,
      "y": 36,
      "z": 61,
      "name": "Plant_Coral_Block_Cyan"
    },
    {
      "x": -113,
      "y": 33,
      "z": 62,
      "name": "Cloth_Block_Wool_Gray_Light"
    },
    {
      "x": -113,
      "y": 34,
      "z": 62,
      "name": "Plant_Coral_Block_Cyan"
    },
    {
      "x": -113,
      "y": 35,
      "z": 62,
      "name": "Plant_Coral_Block_Cyan"
    },
    {
      "x": -113,
      "y": 36,
      "z": 62,
      "name": "Plant_Coral_Block_Cyan"
    },
    {
      "x": -113,
      "y": 33,
      "z": 63,
      "name": "Cloth_Block_Wool_Gray_Light"
    },
    {
      "x": -113,
      "y": 33,
      "z": 64,
      "name": "Cloth_Block_Wool_Gray_Light"
    },
    {
      "x": -113,
      "y": 33,
      "z": 65,
      "name": "Cloth_Block_Wool_Gray_Light"
    },
    {
      "x": -113,
      "y": 34,
      "z": 65,
      "name": "Plant_Coral_Block_Yellow"
    },
    {
      "x": -113,
      "y": 35,
      "z": 65,
      "name": "Plant_Coral_Block_Yellow"
    },
    {
      "x": -113,
      "y": 36,
      "z": 65,
      "name": "Plant_Coral_Block_Yellow"
    },
    {
      "x": -113,
      "y": 33,
      "z": 66,
      "name": "Cloth_Block_Wool_Gray_Light"
    },
    {
      "x": -113,
      "y": 34,
      "z": 66,
      "name": "Plant_Coral_Block_Yellow"
    },
    {
      "x": -113,
      "y": 35,
      "z": 66,
      "name": "Plant_Coral_Block_Yellow"
    },
    {
      "x": -113,
      "y": 36,
      "z": 66,
      "name": "Plant_Coral_Block_Yellow"
    },
    {
      "x": -113,
      "y": 33,
      "z": 67,
      "name": "Cloth_Block_Wool_Gray_Light"
    },
    {
      "x": -113,
      "y": 34,
      "z": 67,
      "name": "Plant_Coral_Block_Yellow"
    },
    {
      "x": -113,
      "y": 35,
      "z": 67,
      "name": "Rock_Crystal_Yellow_Block"
    },
    {
      "x": -113,
      "y": 36,
      "z": 67,
      "name": "Plant_Coral_Bush_Yellow"
    },
    {
      "x": -113,
      "y": 33,
      "z": 68,
      "name": "Cloth_Block_Wool_Gray_Light"
    },
    {
      "x": -113,
      "y": 34,
      "z": 68,
      "name": "Plant_Coral_Block_Yellow"
    },
    {
      "x": -113,
      "y": 35,
      "z": 68,
      "name": "Plant_Coral_Block_Yellow"
    },
    {
      "x": -113,
      "y": 36,
      "z": 68,
      "name": "Plant_Coral_Block_Yellow"
    },
    {
      "x": -113,
      "y": 33,
      "z": 69,
      "name": "Cloth_Block_Wool_Gray_Light"
    },
    {
      "x": -113,
      "y": 34,
      "z": 69,
      "name": "Plant_Coral_Block_Yellow"
    },
    {
      "x": -113,
      "y": 35,
      "z": 69,
      "name": "Plant_Coral_Block_Yellow"
    },
    {
      "x": -113,
      "y": 36,
      "z": 69,
      "name": "Plant_Coral_Block_Yellow"
    },
    {
      "x": -113,
      "y": 33,
      "z": 70,
      "name": "Cloth_Block_Wool_Gray_Light"
    },
    {
      "x": -113,
      "y": 33,
      "z": 71,
      "name": "Cloth_Block_Wool_Gray_Light"
    },
    {
      "x": -113,
      "y": 33,
      "z": 72,
      "name": "Cloth_Block_Wool_Gray_Light"
    },
    {
      "x": -113,
      "y": 34,
      "z": 72,
      "name": "Plant_Coral_Block_Lime"
    },
    {
      "x": -113,
      "y": 35,
      "z": 72,
      "name": "Plant_Coral_Block_Lime"
    },
    {
      "x": -113,
      "y": 33,
      "z": 73,
      "name": "Cloth_Block_Wool_Gray_Light"
    },
    {
      "x": -113,
      "y": 34,
      "z": 73,
      "name": "Plant_Coral_Block_Lime"
    },
    {
      "x": -113,
      "y": 35,
      "z": 73,
      "name": "Plant_Coral_Block_Lime"
    },
    {
      "x": -113,
      "y": 36,
      "z": 73,
      "name": "Plant_Coral_Block_Lime"
    },
    {
      "x": -113,
      "y": 33,
      "z": 74,
      "name": "Cloth_Block_Wool_Gray_Light"
    },
    {
      "x": -113,
      "y": 34,
      "z": 74,
      "name": "Plant_Coral_Block_Lime"
    },
    {
      "x": -113,
      "y": 35,
      "z": 74,
      "name": "Rock_Crystal_Green_Block"
    },
    {
      "x": -113,
      "y": 36,
      "z": 74,
      "name": "Plant_Coral_Bush_Green"
    },
    {
      "x": -113,
      "y": 33,
      "z": 75,
      "name": "Cloth_Block_Wool_Gray_Light"
    },
    {
      "x": -113,
      "y": 34,
      "z": 75,
      "name": "Plant_Coral_Block_Lime"
    },
    {
      "x": -113,
      "y": 35,
      "z": 75,
      "name": "Rock_Crystal_Green_Block"
    },
    {
      "x": -113,
      "y": 36,
      "z": 75,
      "name": "Rock_Crystal_Green_Medium"
    },
    {
      "x": -113,
      "y": 33,
      "z": 76,
      "name": "Cloth_Block_Wool_Gray_Light"
    },
    {
      "x": -113,
      "y": 34,
      "z": 76,
      "name": "Plant_Coral_Block_Lime"
    },
    {
      "x": -113,
      "y": 35,
      "z": 76,
      "name": "Rock_Crystal_Green_Block"
    },
    {
      "x": -113,
      "y": 33,
      "z": 77,
      "name": "Cloth_Block_Wool_Gray_Light"
    },
    {
      "x": -113,
      "y": 34,
      "z": 77,
      "name": "Plant_Coral_Block_Lime"
    },
    {
      "x": -113,
      "y": 35,
      "z": 77,
      "name": "Plant_Coral_Block_Lime"
    },
    {
      "x": -113,
      "y": 36,
      "z": 77,
      "name": "Plant_Coral_Block_Lime"
    },
    {
      "x": -113,
      "y": 33,
      "z": 78,
      "name": "Cloth_Block_Wool_Gray_Light"
    },
    {
      "x": -113,
      "y": 33,
      "z": 79,
      "name": "Cloth_Block_Wool_Gray_Light"
    },
    {
      "x": -113,
      "y": 34,
      "z": 79,
      "name": "Plant_Coral_Block_Purple"
    },
    {
      "x": -113,
      "y": 35,
      "z": 79,
      "name": "Plant_Coral_Block_Purple"
    },
    {
      "x": -113,
      "y": 33,
      "z": 80,
      "name": "Cloth_Block_Wool_Gray_Light"
    },
    {
      "x": -113,
      "y": 34,
      "z": 80,
      "name": "Plant_Coral_Block_Purple"
    },
    {
      "x": -113,
      "y": 35,
      "z": 80,
      "name": "Plant_Coral_Block_Purple"
    },
    {
      "x": -113,
      "y": 36,
      "z": 80,
      "name": "Plant_Coral_Block_Purple"
    },
    {
      "x": -113,
      "y": 33,
      "z": 81,
      "name": "Cloth_Block_Wool_Gray_Light"
    },
    {
      "x": -113,
      "y": 34,
      "z": 81,
      "name": "Plant_Coral_Block_Purple"
    },
    {
      "x": -113,
      "y": 35,
      "z": 81,
      "name": "Plant_Coral_Block_Purple"
    },
    {
      "x": -113,
      "y": 36,
      "z": 81,
      "name": "Plant_Coral_Block_Purple"
    },
    {
      "x": -113,
      "y": 33,
      "z": 82,
      "name": "Cloth_Block_Wool_Gray_Light"
    },
    {
      "x": -113,
      "y": 34,
      "z": 82,
      "name": "Plant_Coral_Block_Purple"
    },
    {
      "x": -113,
      "y": 35,
      "z": 82,
      "name": "Rock_Crystal_Purple_Block"
    },
    {
      "x": -113,
      "y": 33,
      "z": 83,
      "name": "Cloth_Block_Wool_Gray_Light"
    },
    {
      "x": -113,
      "y": 34,
      "z": 83,
      "name": "Plant_Coral_Block_Purple"
    },
    {
      "x": -113,
      "y": 35,
      "z": 83,
      "name": "Rock_Crystal_Purple_Block"
    },
    {
      "x": -113,
      "y": 36,
      "z": 83,
      "name": "Plant_Coral_Bush_Purple"
    },
    {
      "x": -113,
      "y": 33,
      "z": 84,
      "name": "Cloth_Block_Wool_Gray_Light"
    },
    {
      "x": -113,
      "y": 34,
      "z": 84,
      "name": "Plant_Coral_Block_Purple"
    },
    {
      "x": -113,
      "y": 35,
      "z": 84,
      "name": "Plant_Coral_Block_Purple"
    },
    {
      "x": -113,
      "y": 33,
      "z": 85,
      "name": "Cloth_Block_Wool_Gray_Light"
    },
    {
      "x": -112,
      "y": 33,
      "z": -84,
      "name": "Cloth_Block_Wool_Gray_Light"
    },
    {
      "x": -112,
      "y": 33,
      "z": -83,
      "name": "Cloth_Block_Wool_Gray_Light"
    },
    {
      "x": -112,
      "y": 33,
      "z": -82,
      "name": "Cloth_Block_Wool_Gray_Light"
    },
    {
      "x": -112,
      "y": 33,
      "z": -81,
      "name": "Cloth_Block_Wool_Gray_Light"
    },
    {
      "x": -112,
      "y": 33,
      "z": -80,
      "name": "Cloth_Block_Wool_Gray_Light"
    },
    {
      "x": -112,
      "y": 33,
      "z": -79,
      "name": "Cloth_Block_Wool_Gray_Light"
    },
    {
      "x": -112,
      "y": 33,
      "z": -78,
      "name": "Cloth_Block_Wool_Gray_Light"
    },
    {
      "x": -112,
      "y": 33,
      "z": -77,
      "name": "Cloth_Block_Wool_Gray_Light"
    },
    {
      "x": -112,
      "y": 33,
      "z": -76,
      "name": "Cloth_Block_Wool_Gray_Light"
    },
    {
      "x": -112,
      "y": 33,
      "z": -75,
      "name": "Cloth_Block_Wool_Gray_Light"
    },
    {
      "x": -112,
      "y": 33,
      "z": -74,
      "name": "Cloth_Block_Wool_Gray_Light"
    },
    {
      "x": -112,
      "y": 33,
      "z": -73,
      "name": "Cloth_Block_Wool_Gray_Light"
    },
    {
      "x": -112,
      "y": 33,
      "z": -72,
      "name": "Cloth_Block_Wool_Gray_Light"
    },
    {
      "x": -112,
      "y": 33,
      "z": -71,
      "name": "Cloth_Block_Wool_Gray_Light"
    },
    {
      "x": -112,
      "y": 33,
      "z": -70,
      "name": "Cloth_Block_Wool_Gray_Light"
    },
    {
      "x": -112,
      "y": 33,
      "z": -69,
      "name": "Cloth_Block_Wool_Gray_Light"
    },
    {
      "x": -112,
      "y": 33,
      "z": -68,
      "name": "Cloth_Block_Wool_Gray_Light"
    },
    {
      "x": -112,
      "y": 33,
      "z": -67,
      "name": "Cloth_Block_Wool_Gray_Light"
    },
    {
      "x": -112,
      "y": 33,
      "z": -66,
      "name": "Cloth_Block_Wool_Gray_Light"
    },
    {
      "x": -112,
      "y": 33,
      "z": -65,
      "name": "Cloth_Block_Wool_Gray_Light"
    },
    {
      "x": -112,
      "y": 33,
      "z": -64,
      "name": "Cloth_Block_Wool_Gray_Light"
    },
    {
      "x": -112,
      "y": 33,
      "z": -63,
      "name": "Cloth_Block_Wool_Gray_Light"
    },
    {
      "x": -112,
      "y": 33,
      "z": -62,
      "name": "Cloth_Block_Wool_Gray_Light"
    },
    {
      "x": -112,
      "y": 33,
      "z": -61,
      "name": "Cloth_Block_Wool_Gray_Light"
    },
    {
      "x": -112,
      "y": 33,
      "z": -60,
      "name": "Cloth_Block_Wool_Gray_Light"
    },
    {
      "x": -112,
      "y": 33,
      "z": -59,
      "name": "Cloth_Block_Wool_Gray_Light"
    },
    {
      "x": -112,
      "y": 33,
      "z": -58,
      "name": "Cloth_Block_Wool_Gray_Light"
    },
    {
      "x": -112,
      "y": 33,
      "z": -57,
      "name": "Cloth_Block_Wool_Gray_Light"
    },
    {
      "x": -112,
      "y": 33,
      "z": -56,
      "name": "Cloth_Block_Wool_Gray_Light"
    },
    {
      "x": -112,
      "y": 33,
      "z": -55,
      "name": "Cloth_Block_Wool_Gray_Light"
    },
    {
      "x": -112,
      "y": 33,
      "z": -54,
      "name": "Cloth_Block_Wool_Gray_Light"
    },
    {
      "x": -112,
      "y": 33,
      "z": -53,
      "name": "Cloth_Block_Wool_Gray_Light"
    },
    {
      "x": -112,
      "y": 33,
      "z": -52,
      "name": "Cloth_Block_Wool_Gray_Light"
    },
    {
      "x": -112,
      "y": 33,
      "z": -51,
      "name": "Cloth_Block_Wool_Gray_Light"
    },
    {
      "x": -112,
      "y": 33,
      "z": -50,
      "name": "Cloth_Block_Wool_Gray_Light"
    },
    {
      "x": -112,
      "y": 33,
      "z": -49,
      "name": "Cloth_Block_Wool_Gray_Light"
    },
    {
      "x": -112,
      "y": 33,
      "z": -48,
      "name": "Cloth_Block_Wool_Gray_Light"
    },
    {
      "x": -112,
      "y": 33,
      "z": -47,
      "name": "Cloth_Block_Wool_Gray_Light"
    },
    {
      "x": -112,
      "y": 33,
      "z": -46,
      "name": "Cloth_Block_Wool_Gray_Light"
    },
    {
      "x": -112,
      "y": 33,
      "z": -45,
      "name": "Cloth_Block_Wool_Gray_Light"
    },
    {
      "x": -112,
      "y": 33,
      "z": -44,
      "name": "Cloth_Block_Wool_Gray_Light"
    },
    {
      "x": -112,
      "y": 33,
      "z": -43,
      "name": "Cloth_Block_Wool_Gray_Light"
    },
    {
      "x": -112,
      "y": 33,
      "z": -42,
      "name": "Cloth_Block_Wool_Gray_Light"
    },
    {
      "x": -112,
      "y": 33,
      "z": -41,
      "name": "Cloth_Block_Wool_Gray_Light"
    },
    {
      "x": -112,
      "y": 33,
      "z": -40,
      "name": "Cloth_Block_Wool_Gray_Light"
    },
    {
      "x": -112,
      "y": 33,
      "z": -39,
      "name": "Cloth_Block_Wool_Gray_Light"
    },
    {
      "x": -112,
      "y": 33,
      "z": -38,
      "name": "Cloth_Block_Wool_Gray_Light"
    },
    {
      "x": -112,
      "y": 33,
      "z": -37,
      "name": "Cloth_Block_Wool_Gray_Light"
    },
    {
      "x": -112,
      "y": 33,
      "z": -36,
      "name": "Cloth_Block_Wool_Gray_Light"
    },
    {
      "x": -112,
      "y": 33,
      "z": -35,
      "name": "Cloth_Block_Wool_Gray_Light"
    },
    {
      "x": -112,
      "y": 33,
      "z": -34,
      "name": "Cloth_Block_Wool_Gray_Light"
    },
    {
      "x": -112,
      "y": 33,
      "z": -33,
      "name": "Cloth_Block_Wool_Gray_Light"
    },
    {
      "x": -112,
      "y": 33,
      "z": -32,
      "name": "Cloth_Block_Wool_Gray_Light"
    },
    {
      "x": -112,
      "y": 33,
      "z": -31,
      "name": "Cloth_Block_Wool_Gray_Light"
    },
    {
      "x": -112,
      "y": 33,
      "z": -30,
      "name": "Cloth_Block_Wool_Gray_Light"
    },
    {
      "x": -112,
      "y": 33,
      "z": -29,
      "name": "Cloth_Block_Wool_Gray_Light"
    },
    {
      "x": -112,
      "y": 33,
      "z": -28,
      "name": "Cloth_Block_Wool_Gray_Light"
    },
    {
      "x": -112,
      "y": 33,
      "z": -27,
      "name": "Cloth_Block_Wool_Gray_Light"
    },
    {
      "x": -112,
      "y": 33,
      "z": -26,
      "name": "Cloth_Block_Wool_Gray_Light"
    },
    {
      "x": -112,
      "y": 33,
      "z": -25,
      "name": "Cloth_Block_Wool_Gray_Light"
    },
    {
      "x": -112,
      "y": 33,
      "z": -24,
      "name": "Cloth_Block_Wool_Gray_Light"
    },
    {
      "x": -112,
      "y": 33,
      "z": -23,
      "name": "Cloth_Block_Wool_Gray_Light"
    },
    {
      "x": -112,
      "y": 33,
      "z": -22,
      "name": "Cloth_Block_Wool_Gray_Light"
    },
    {
      "x": -112,
      "y": 33,
      "z": -21,
      "name": "Cloth_Block_Wool_Gray_Light"
    },
    {
      "x": -112,
      "y": 33,
      "z": -20,
      "name": "Cloth_Block_Wool_Gray_Light"
    },
    {
      "x": -112,
      "y": 33,
      "z": -19,
      "name": "Cloth_Block_Wool_Gray_Light"
    },
    {
      "x": -112,
      "y": 33,
      "z": -18,
      "name": "Cloth_Block_Wool_Gray_Light"
    },
    {
      "x": -112,
      "y": 33,
      "z": -17,
      "name": "Cloth_Block_Wool_Gray_Light"
    },
    {
      "x": -112,
      "y": 33,
      "z": -16,
      "name": "Cloth_Block_Wool_Gray_Light"
    },
    {
      "x": -112,
      "y": 33,
      "z": -15,
      "name": "Cloth_Block_Wool_Gray_Light"
    },
    {
      "x": -112,
      "y": 33,
      "z": -14,
      "name": "Cloth_Block_Wool_Gray_Light"
    },
    {
      "x": -112,
      "y": 33,
      "z": -13,
      "name": "Cloth_Block_Wool_Gray_Light"
    },
    {
      "x": -112,
      "y": 33,
      "z": -12,
      "name": "Cloth_Block_Wool_Gray_Light"
    },
    {
      "x": -112,
      "y": 33,
      "z": -11,
      "name": "Cloth_Block_Wool_Gray_Light"
    },
    {
      "x": -112,
      "y": 33,
      "z": -10,
      "name": "Cloth_Block_Wool_Gray_Light"
    },
    {
      "x": -112,
      "y": 33,
      "z": -9,
      "name": "Cloth_Block_Wool_Gray_Light"
    },
    {
      "x": -112,
      "y": 33,
      "z": -8,
      "name": "Cloth_Block_Wool_Gray_Light"
    },
    {
      "x": -112,
      "y": 33,
      "z": -7,
      "name": "Cloth_Block_Wool_Gray_Light"
    },
    {
      "x": -112,
      "y": 33,
      "z": -6,
      "name": "Cloth_Block_Wool_Gray_Light"
    },
    {
      "x": -112,
      "y": 33,
      "z": -5,
      "name": "Cloth_Block_Wool_Gray_Light"
    },
    {
      "x": -112,
      "y": 33,
      "z": -4,
      "name": "Cloth_Block_Wool_Gray_Light"
    },
    {
      "x": -112,
      "y": 33,
      "z": -3,
      "name": "Cloth_Block_Wool_Gray_Light"
    },
    {
      "x": -112,
      "y": 33,
      "z": -2,
      "name": "Cloth_Block_Wool_Gray_Light"
    },
    {
      "x": -112,
      "y": 33,
      "z": -1,
      "name": "Cloth_Block_Wool_Gray_Light"
    },
    {
      "x": -112,
      "y": 33,
      "z": 0,
      "name": "Cloth_Block_Wool_Gray_Light"
    },
    {
      "x": -112,
      "y": 33,
      "z": 1,
      "name": "Cloth_Block_Wool_Gray_Light"
    },
    {
      "x": -112,
      "y": 33,
      "z": 2,
      "name": "Cloth_Block_Wool_Gray_Light"
    },
    {
      "x": -112,
      "y": 33,
      "z": 3,
      "name": "Cloth_Block_Wool_Gray_Light"
    },
    {
      "x": -112,
      "y": 33,
      "z": 4,
      "name": "Cloth_Block_Wool_Gray_Light"
    },
    {
      "x": -112,
      "y": 33,
      "z": 5,
      "name": "Cloth_Block_Wool_Gray_Light"
    },
    {
      "x": -112,
      "y": 33,
      "z": 6,
      "name": "Cloth_Block_Wool_Gray_Light"
    },
    {
      "x": -112,
      "y": 33,
      "z": 7,
      "name": "Cloth_Block_Wool_Gray_Light"
    },
    {
      "x": -112,
      "y": 33,
      "z": 8,
      "name": "Cloth_Block_Wool_Gray_Light"
    },
    {
      "x": -112,
      "y": 33,
      "z": 9,
      "name": "Cloth_Block_Wool_Gray_Light"
    },
    {
      "x": -112,
      "y": 33,
      "z": 10,
      "name": "Cloth_Block_Wool_Gray_Light"
    },
    {
      "x": -112,
      "y": 33,
      "z": 11,
      "name": "Cloth_Block_Wool_Gray_Light"
    },
    {
      "x": -112,
      "y": 33,
      "z": 12,
      "name": "Cloth_Block_Wool_Gray_Light"
    },
    {
      "x": -112,
      "y": 33,
      "z": 13,
      "name": "Cloth_Block_Wool_Gray_Light"
    },
    {
      "x": -112,
      "y": 33,
      "z": 14,
      "name": "Cloth_Block_Wool_Gray_Light"
    },
    {
      "x": -112,
      "y": 33,
      "z": 15,
      "name": "Cloth_Block_Wool_Gray_Light"
    },
    {
      "x": -112,
      "y": 33,
      "z": 16,
      "name": "Cloth_Block_Wool_Gray_Light"
    },
    {
      "x": -112,
      "y": 33,
      "z": 17,
      "name": "Cloth_Block_Wool_Gray_Light"
    },
    {
      "x": -112,
      "y": 33,
      "z": 18,
      "name": "Cloth_Block_Wool_Gray_Light"
    },
    {
      "x": -112,
      "y": 33,
      "z": 19,
      "name": "Cloth_Block_Wool_Gray_Light"
    },
    {
      "x": -112,
      "y": 33,
      "z": 20,
      "name": "Cloth_Block_Wool_Gray_Light"
    },
    {
      "x": -112,
      "y": 33,
      "z": 21,
      "name": "Cloth_Block_Wool_Gray_Light"
    },
    {
      "x": -112,
      "y": 33,
      "z": 22,
      "name": "Cloth_Block_Wool_Gray_Light"
    },
    {
      "x": -112,
      "y": 33,
      "z": 23,
      "name": "Cloth_Block_Wool_Gray_Light"
    },
    {
      "x": -112,
      "y": 33,
      "z": 24,
      "name": "Cloth_Block_Wool_Gray_Light"
    },
    {
      "x": -112,
      "y": 33,
      "z": 25,
      "name": "Cloth_Block_Wool_Gray_Light"
    },
    {
      "x": -112,
      "y": 33,
      "z": 26,
      "name": "Cloth_Block_Wool_Gray_Light"
    },
    {
      "x": -112,
      "y": 33,
      "z": 27,
      "name": "Cloth_Block_Wool_Gray_Light"
    },
    {
      "x": -112,
      "y": 33,
      "z": 28,
      "name": "Cloth_Block_Wool_Gray_Light"
    },
    {
      "x": -112,
      "y": 33,
      "z": 29,
      "name": "Cloth_Block_Wool_Gray_Light"
    },
    {
      "x": -112,
      "y": 33,
      "z": 30,
      "name": "Cloth_Block_Wool_Gray_Light"
    },
    {
      "x": -112,
      "y": 33,
      "z": 31,
      "name": "Cloth_Block_Wool_Gray_Light"
    },
    {
      "x": -112,
      "y": 33,
      "z": 32,
      "name": "Cloth_Block_Wool_Gray_Light"
    },
    {
      "x": -112,
      "y": 33,
      "z": 33,
      "name": "Cloth_Block_Wool_Gray_Light"
    },
    {
      "x": -112,
      "y": 33,
      "z": 34,
      "name": "Cloth_Block_Wool_Gray_Light"
    },
    {
      "x": -112,
      "y": 33,
      "z": 35,
      "name": "Cloth_Block_Wool_Gray_Light"
    },
    {
      "x": -112,
      "y": 39,
      "z": 35,
      "name": "Plant_Leaves_Jungle"
    },
    {
      "x": -112,
      "y": 33,
      "z": 36,
      "name": "Cloth_Block_Wool_Gray_Light"
    },
    {
      "x": -112,
      "y": 39,
      "z": 36,
      "name": "Plant_Leaves_Jungle"
    },
    {
      "x": -112,
      "y": 33,
      "z": 37,
      "name": "Cloth_Block_Wool_Gray_Light"
    },
    {
      "x": -112,
      "y": 40,
      "z": 37,
      "name": "Plant_Leaves_Jungle"
    },
    {
      "x": -112,
      "y": 33,
      "z": 38,
      "name": "Cloth_Block_Wool_Gray_Light"
    },
    {
      "x": -112,
      "y": 38,
      "z": 38,
      "name": "Plant_Leaves_Jungle"
    },
    {
      "x": -112,
      "y": 39,
      "z": 38,
      "name": "Plant_Leaves_Jungle"
    },
    {
      "x": -112,
      "y": 33,
      "z": 39,
      "name": "Cloth_Block_Wool_Gray_Light"
    },
    {
      "x": -112,
      "y": 38,
      "z": 39,
      "name": "Plant_Leaves_Jungle"
    },
    {
      "x": -112,
      "y": 39,
      "z": 39,
      "name": "Plant_Leaves_Jungle"
    },
    {
      "x": -112,
      "y": 40,
      "z": 39,
      "name": "Plant_Leaves_Jungle"
    },
    {
      "x": -112,
      "y": 33,
      "z": 40,
      "name": "Cloth_Block_Wool_Gray_Light"
    },
    {
      "x": -112,
      "y": 34,
      "z": 40,
      "name": "Wood_Jungle_Trunk"
    },
    {
      "x": -112,
      "y": 35,
      "z": 40,
      "name": "Wood_Jungle_Trunk"
    },
    {
      "x": -112,
      "y": 36,
      "z": 40,
      "name": "Wood_Jungle_Trunk"
    },
    {
      "x": -112,
      "y": 37,
      "z": 40,
      "name": "Wood_Jungle_Trunk_Full"
    },
    {
      "x": -112,
      "y": 38,
      "z": 40,
      "name": "Plant_Leaves_Jungle"
    },
    {
      "x": -112,
      "y": 33,
      "z": 41,
      "name": "Cloth_Block_Wool_Gray_Light"
    },
    {
      "x": -112,
      "y": 37,
      "z": 41,
      "name": "Plant_Leaves_Jungle"
    },
    {
      "x": -112,
      "y": 33,
      "z": 42,
      "name": "Cloth_Block_Wool_Gray_Light"
    },
    {
      "x": -112,
      "y": 33,
      "z": 43,
      "name": "Cloth_Block_Wool_Gray_Light"
    },
    {
      "x": -112,
      "y": 33,
      "z": 44,
      "name": "Cloth_Block_Wool_Gray_Light"
    },
    {
      "x": -112,
      "y": 33,
      "z": 45,
      "name": "Cloth_Block_Wool_Gray_Light"
    },
    {
      "x": -112,
      "y": 33,
      "z": 46,
      "name": "Cloth_Block_Wool_Gray_Light"
    },
    {
      "x": -112,
      "y": 33,
      "z": 47,
      "name": "Cloth_Block_Wool_Gray_Light"
    },
    {
      "x": -112,
      "y": 33,
      "z": 48,
      "name": "Cloth_Block_Wool_Gray_Light"
    },
    {
      "x": -112,
      "y": 33,
      "z": 49,
      "name": "Cloth_Block_Wool_Gray_Light"
    },
    {
      "x": -112,
      "y": 33,
      "z": 50,
      "name": "Cloth_Block_Wool_Gray_Light"
    },
    {
      "x": -112,
      "y": 34,
      "z": 50,
      "name": "Plant_Fern_Jungle_Trunk"
    },
    {
      "x": -112,
      "y": 35,
      "z": 50,
      "name": "Plant_Fern_Jungle_Trunk"
    },
    {
      "x": -112,
      "y": 36,
      "z": 50,
      "name": "Plant_Fern_Jungle_Trunk"
    },
    {
      "x": -112,
      "y": 37,
      "z": 50,
      "name": "Wood_Jungle_Branch_Long"
    },
    {
      "x": -112,
      "y": 38,
      "z": 50,
      "name": "Wood_Jungle_Branch_Long"
    },
    {
      "x": -112,
      "y": 39,
      "z": 50,
      "name": "Plant_Fern_Jungle"
    },
    {
      "x": -112,
      "y": 33,
      "z": 51,
      "name": "Cloth_Block_Wool_Gray_Light"
    },
    {
      "x": -112,
      "y": 33,
      "z": 52,
      "name": "Cloth_Block_Wool_Gray_Light"
    },
    {
      "x": -112,
      "y": 33,
      "z": 53,
      "name": "Cloth_Block_Wool_Gray_Light"
    },
    {
      "x": -112,
      "y": 33,
      "z": 54,
      "name": "Cloth_Block_Wool_Gray_Light"
    },
    {
      "x": -112,
      "y": 33,
      "z": 55,
      "name": "Cloth_Block_Wool_Gray_Light"
    },
    {
      "x": -112,
      "y": 33,
      "z": 56,
      "name": "Cloth_Block_Wool_Gray_Light"
    },
    {
      "x": -112,
      "y": 33,
      "z": 57,
      "name": "Cloth_Block_Wool_Gray_Light"
    },
    {
      "x": -112,
      "y": 33,
      "z": 58,
      "name": "Cloth_Block_Wool_Gray_Light"
    },
    {
      "x": -112,
      "y": 33,
      "z": 59,
      "name": "Cloth_Block_Wool_Gray_Light"
    },
    {
      "x": -112,
      "y": 34,
      "z": 59,
      "name": "Plant_Coral_Block_Cyan"
    },
    {
      "x": -112,
      "y": 35,
      "z": 59,
      "name": "Plant_Coral_Block_Cyan"
    },
    {
      "x": -112,
      "y": 36,
      "z": 59,
      "name": "Plant_Coral_Block_Cyan"
    },
    {
      "x": -112,
      "y": 33,
      "z": 60,
      "name": "Cloth_Block_Wool_Gray_Light"
    },
    {
      "x": -112,
      "y": 34,
      "z": 60,
      "name": "Plant_Coral_Block_Cyan"
    },
    {
      "x": -112,
      "y": 35,
      "z": 60,
      "name": "Plant_Coral_Block_Cyan"
    },
    {
      "x": -112,
      "y": 36,
      "z": 60,
      "name": "Plant_Coral_Block_Cyan"
    },
    {
      "x": -112,
      "y": 33,
      "z": 61,
      "name": "Cloth_Block_Wool_Gray_Light"
    },
    {
      "x": -112,
      "y": 34,
      "z": 61,
      "name": "Plant_Coral_Block_Cyan"
    },
    {
      "x": -112,
      "y": 35,
      "z": 61,
      "name": "Rock_Crystal_Cyan_Block"
    },
    {
      "x": -112,
      "y": 36,
      "z": 61,
      "name": "Plant_Coral_Bush_Cyan"
    },
    {
      "x": -112,
      "y": 37,
      "z": 61,
      "name": "Plant_Coral_Bush_Cyan"
    },
    {
      "x": -112,
      "y": 33,
      "z": 62,
      "name": "Cloth_Block_Wool_Gray_Light"
    },
    {
      "x": -112,
      "y": 34,
      "z": 62,
      "name": "Plant_Coral_Block_Cyan"
    },
    {
      "x": -112,
      "y": 35,
      "z": 62,
      "name": "Rock_Crystal_Cyan_Block"
    },
    {
      "x": -112,
      "y": 33,
      "z": 63,
      "name": "Cloth_Block_Wool_Gray_Light"
    },
    {
      "x": -112,
      "y": 34,
      "z": 63,
      "name": "Plant_Coral_Block_Cyan"
    },
    {
      "x": -112,
      "y": 35,
      "z": 63,
      "name": "Plant_Coral_Block_Cyan"
    },
    {
      "x": -112,
      "y": 36,
      "z": 63,
      "name": "Plant_Coral_Block_Cyan"
    },
    {
      "x": -112,
      "y": 33,
      "z": 64,
      "name": "Cloth_Block_Wool_Gray_Light"
    },
    {
      "x": -112,
      "y": 33,
      "z": 65,
      "name": "Cloth_Block_Wool_Gray_Light"
    },
    {
      "x": -112,
      "y": 34,
      "z": 65,
      "name": "Plant_Coral_Block_Yellow"
    },
    {
      "x": -112,
      "y": 35,
      "z": 65,
      "name": "Plant_Coral_Block_Yellow"
    },
    {
      "x": -112,
      "y": 36,
      "z": 65,
      "name": "Plant_Coral_Block_Yellow"
    },
    {
      "x": -112,
      "y": 33,
      "z": 66,
      "name": "Cloth_Block_Wool_Gray_Light"
    },
    {
      "x": -112,
      "y": 34,
      "z": 66,
      "name": "Plant_Coral_Block_Yellow"
    },
    {
      "x": -112,
      "y": 35,
      "z": 66,
      "name": "Rock_Crystal_Yellow_Block"
    },
    {
      "x": -112,
      "y": 33,
      "z": 67,
      "name": "Cloth_Block_Wool_Gray_Light"
    },
    {
      "x": -112,
      "y": 34,
      "z": 67,
      "name": "Plant_Coral_Block_Yellow"
    },
    {
      "x": -112,
      "y": 35,
      "z": 67,
      "name": "Rock_Crystal_Yellow_Block"
    },
    {
      "x": -112,
      "y": 33,
      "z": 68,
      "name": "Cloth_Block_Wool_Gray_Light"
    },
    {
      "x": -112,
      "y": 34,
      "z": 68,
      "name": "Plant_Coral_Block_Yellow"
    },
    {
      "x": -112,
      "y": 35,
      "z": 68,
      "name": "Rock_Crystal_Yellow_Block"
    },
    {
      "x": -112,
      "y": 36,
      "z": 68,
      "name": "Rock_Crystal_Yellow_Medium"
    },
    {
      "x": -112,
      "y": 33,
      "z": 69,
      "name": "Cloth_Block_Wool_Gray_Light"
    },
    {
      "x": -112,
      "y": 34,
      "z": 69,
      "name": "Plant_Coral_Block_Yellow"
    },
    {
      "x": -112,
      "y": 35,
      "z": 69,
      "name": "Plant_Coral_Block_Yellow"
    },
    {
      "x": -112,
      "y": 36,
      "z": 69,
      "name": "Plant_Coral_Block_Yellow"
    },
    {
      "x": -112,
      "y": 33,
      "z": 70,
      "name": "Cloth_Block_Wool_Gray_Light"
    },
    {
      "x": -112,
      "y": 34,
      "z": 70,
      "name": "Plant_Coral_Block_Yellow"
    },
    {
      "x": -112,
      "y": 35,
      "z": 70,
      "name": "Plant_Coral_Block_Yellow"
    },
    {
      "x": -112,
      "y": 36,
      "z": 70,
      "name": "Plant_Coral_Block_Yellow"
    },
    {
      "x": -112,
      "y": 33,
      "z": 71,
      "name": "Cloth_Block_Wool_Gray_Light"
    },
    {
      "x": -112,
      "y": 33,
      "z": 72,
      "name": "Cloth_Block_Wool_Gray_Light"
    },
    {
      "x": -112,
      "y": 34,
      "z": 72,
      "name": "Plant_Coral_Block_Lime"
    },
    {
      "x": -112,
      "y": 35,
      "z": 72,
      "name": "Plant_Coral_Block_Lime"
    },
    {
      "x": -112,
      "y": 36,
      "z": 72,
      "name": "Plant_Coral_Block_Lime"
    },
    {
      "x": -112,
      "y": 33,
      "z": 73,
      "name": "Cloth_Block_Wool_Gray_Light"
    },
    {
      "x": -112,
      "y": 34,
      "z": 73,
      "name": "Plant_Coral_Block_Lime"
    },
    {
      "x": -112,
      "y": 35,
      "z": 73,
      "name": "Rock_Crystal_Green_Block"
    },
    {
      "x": -112,
      "y": 33,
      "z": 74,
      "name": "Cloth_Block_Wool_Gray_Light"
    },
    {
      "x": -112,
      "y": 34,
      "z": 74,
      "name": "Plant_Coral_Block_Lime"
    },
    {
      "x": -112,
      "y": 35,
      "z": 74,
      "name": "Rock_Crystal_Green_Block"
    },
    {
      "x": -112,
      "y": 33,
      "z": 75,
      "name": "Cloth_Block_Wool_Gray_Light"
    },
    {
      "x": -112,
      "y": 34,
      "z": 75,
      "name": "Plant_Coral_Block_Lime"
    },
    {
      "x": -112,
      "y": 35,
      "z": 75,
      "name": "Rock_Crystal_Green_Block"
    },
    {
      "x": -112,
      "y": 33,
      "z": 76,
      "name": "Cloth_Block_Wool_Gray_Light"
    },
    {
      "x": -112,
      "y": 34,
      "z": 76,
      "name": "Plant_Coral_Block_Lime"
    },
    {
      "x": -112,
      "y": 35,
      "z": 76,
      "name": "Rock_Crystal_Green_Block"
    },
    {
      "x": -112,
      "y": 36,
      "z": 76,
      "name": "Rock_Crystal_Green_Medium"
    },
    {
      "x": -112,
      "y": 33,
      "z": 77,
      "name": "Cloth_Block_Wool_Gray_Light"
    },
    {
      "x": -112,
      "y": 34,
      "z": 77,
      "name": "Plant_Coral_Block_Lime"
    },
    {
      "x": -112,
      "y": 35,
      "z": 77,
      "name": "Plant_Coral_Block_Lime"
    },
    {
      "x": -112,
      "y": 36,
      "z": 77,
      "name": "Plant_Coral_Block_Lime"
    },
    {
      "x": -112,
      "y": 33,
      "z": 78,
      "name": "Cloth_Block_Wool_Gray_Light"
    },
    {
      "x": -112,
      "y": 33,
      "z": 79,
      "name": "Cloth_Block_Wool_Gray_Light"
    },
    {
      "x": -112,
      "y": 34,
      "z": 79,
      "name": "Plant_Coral_Block_Purple"
    },
    {
      "x": -112,
      "y": 35,
      "z": 79,
      "name": "Plant_Coral_Block_Purple"
    },
    {
      "x": -112,
      "y": 36,
      "z": 79,
      "name": "Plant_Coral_Block_Purple"
    },
    {
      "x": -112,
      "y": 33,
      "z": 80,
      "name": "Cloth_Block_Wool_Gray_Light"
    },
    {
      "x": -112,
      "y": 34,
      "z": 80,
      "name": "Plant_Coral_Block_Purple"
    },
    {
      "x": -112,
      "y": 35,
      "z": 80,
      "name": "Rock_Crystal_Purple_Block"
    },
    {
      "x": -112,
      "y": 36,
      "z": 80,
      "name": "Plant_Coral_Bush_Purple"
    },
    {
      "x": -112,
      "y": 33,
      "z": 81,
      "name": "Cloth_Block_Wool_Gray_Light"
    },
    {
      "x": -112,
      "y": 34,
      "z": 81,
      "name": "Plant_Coral_Block_Purple"
    },
    {
      "x": -112,
      "y": 35,
      "z": 81,
      "name": "Rock_Crystal_Purple_Block"
    },
    {
      "x": -112,
      "y": 33,
      "z": 82,
      "name": "Cloth_Block_Wool_Gray_Light"
    },
    {
      "x": -112,
      "y": 34,
      "z": 82,
      "name": "Plant_Coral_Block_Purple"
    },
    {
      "x": -112,
      "y": 35,
      "z": 82,
      "name": "Rock_Crystal_Purple_Block"
    },
    {
      "x": -112,
      "y": 33,
      "z": 83,
      "name": "Cloth_Block_Wool_Gray_Light"
    },
    {
      "x": -112,
      "y": 34,
      "z": 83,
      "name": "Plant_Coral_Block_Purple"
    },
    {
      "x": -112,
      "y": 35,
      "z": 83,
      "name": "Rock_Crystal_Purple_Block"
    },
    {
      "x": -112,
      "y": 33,
      "z": 84,
      "name": "Cloth_Block_Wool_Gray_Light"
    },
    {
      "x": -112,
      "y": 34,
      "z": 84,
      "name": "Plant_Coral_Block_Purple"
    },
    {
      "x": -112,
      "y": 35,
      "z": 84,
      "name": "Plant_Coral_Block_Purple"
    },
    {
      "x": -112,
      "y": 36,
      "z": 84,
      "name": "Plant_Coral_Block_Purple"
    },
    {
      "x": -112,
      "y": 33,
      "z": 85,
      "name": "Cloth_Block_Wool_Gray_Light"
    },
    {
      "x": -111,
      "y": 33,
      "z": -84,
      "name": "Cloth_Block_Wool_Gray_Light"
    },
    {
      "x": -111,
      "y": 33,
      "z": -83,
      "name": "Cloth_Block_Wool_Gray_Light"
    },
    {
      "x": -111,
      "y": 33,
      "z": -82,
      "name": "Cloth_Block_Wool_Gray_Light"
    },
    {
      "x": -111,
      "y": 33,
      "z": -81,
      "name": "Cloth_Block_Wool_Gray_Light"
    },
    {
      "x": -111,
      "y": 33,
      "z": -80,
      "name": "Cloth_Block_Wool_Gray_Light"
    },
    {
      "x": -111,
      "y": 33,
      "z": -79,
      "name": "Cloth_Block_Wool_Gray_Light"
    },
    {
      "x": -111,
      "y": 33,
      "z": -78,
      "name": "Cloth_Block_Wool_Gray_Light"
    },
    {
      "x": -111,
      "y": 33,
      "z": -77,
      "name": "Cloth_Block_Wool_Gray_Light"
    },
    {
      "x": -111,
      "y": 33,
      "z": -76,
      "name": "Cloth_Block_Wool_Gray_Light"
    },
    {
      "x": -111,
      "y": 33,
      "z": -75,
      "name": "Cloth_Block_Wool_Gray_Light"
    },
    {
      "x": -111,
      "y": 33,
      "z": -74,
      "name": "Cloth_Block_Wool_Gray_Light"
    },
    {
      "x": -111,
      "y": 33,
      "z": -73,
      "name": "Cloth_Block_Wool_Gray_Light"
    },
    {
      "x": -111,
      "y": 33,
      "z": -72,
      "name": "Cloth_Block_Wool_Gray_Light"
    },
    {
      "x": -111,
      "y": 33,
      "z": -71,
      "name": "Cloth_Block_Wool_Gray_Light"
    },
    {
      "x": -111,
      "y": 33,
      "z": -70,
      "name": "Cloth_Block_Wool_Gray_Light"
    },
    {
      "x": -111,
      "y": 33,
      "z": -69,
      "name": "Cloth_Block_Wool_Gray_Light"
    },
    {
      "x": -111,
      "y": 33,
      "z": -68,
      "name": "Cloth_Block_Wool_Gray_Light"
    },
    {
      "x": -111,
      "y": 33,
      "z": -67,
      "name": "Cloth_Block_Wool_Gray_Light"
    },
    {
      "x": -111,
      "y": 33,
      "z": -66,
      "name": "Cloth_Block_Wool_Gray_Light"
    },
    {
      "x": -111,
      "y": 33,
      "z": -65,
      "name": "Cloth_Block_Wool_Gray_Light"
    },
    {
      "x": -111,
      "y": 33,
      "z": -64,
      "name": "Cloth_Block_Wool_Gray_Light"
    },
    {
      "x": -111,
      "y": 33,
      "z": -63,
      "name": "Cloth_Block_Wool_Gray_Light"
    },
    {
      "x": -111,
      "y": 33,
      "z": -62,
      "name": "Cloth_Block_Wool_Gray_Light"
    },
    {
      "x": -111,
      "y": 33,
      "z": -61,
      "name": "Cloth_Block_Wool_Gray_Light"
    },
    {
      "x": -111,
      "y": 33,
      "z": -60,
      "name": "Cloth_Block_Wool_Gray_Light"
    },
    {
      "x": -111,
      "y": 33,
      "z": -59,
      "name": "Cloth_Block_Wool_Gray_Light"
    },
    {
      "x": -111,
      "y": 33,
      "z": -58,
      "name": "Cloth_Block_Wool_Gray_Light"
    },
    {
      "x": -111,
      "y": 33,
      "z": -57,
      "name": "Cloth_Block_Wool_Gray_Light"
    },
    {
      "x": -111,
      "y": 33,
      "z": -56,
      "name": "Cloth_Block_Wool_Gray_Light"
    },
    {
      "x": -111,
      "y": 33,
      "z": -55,
      "name": "Cloth_Block_Wool_Gray_Light"
    },
    {
      "x": -111,
      "y": 33,
      "z": -54,
      "name": "Cloth_Block_Wool_Gray_Light"
    },
    {
      "x": -111,
      "y": 33,
      "z": -53,
      "name": "Cloth_Block_Wool_Gray_Light"
    },
    {
      "x": -111,
      "y": 33,
      "z": -52,
      "name": "Cloth_Block_Wool_Gray_Light"
    },
    {
      "x": -111,
      "y": 33,
      "z": -51,
      "name": "Cloth_Block_Wool_Gray_Light"
    },
    {
      "x": -111,
      "y": 33,
      "z": -50,
      "name": "Cloth_Block_Wool_Gray_Light"
    },
    {
      "x": -111,
      "y": 33,
      "z": -49,
      "name": "Cloth_Block_Wool_Gray_Light"
    },
    {
      "x": -111,
      "y": 33,
      "z": -48,
      "name": "Cloth_Block_Wool_Gray_Light"
    },
    {
      "x": -111,
      "y": 33,
      "z": -47,
      "name": "Cloth_Block_Wool_Gray_Light"
    },
    {
      "x": -111,
      "y": 33,
      "z": -46,
      "name": "Cloth_Block_Wool_Gray_Light"
    },
    {
      "x": -111,
      "y": 33,
      "z": -45,
      "name": "Cloth_Block_Wool_Gray_Light"
    },
    {
      "x": -111,
      "y": 33,
      "z": -44,
      "name": "Cloth_Block_Wool_Gray_Light"
    },
    {
      "x": -111,
      "y": 33,
      "z": -43,
      "name": "Cloth_Block_Wool_Gray_Light"
    },
    {
      "x": -111,
      "y": 33,
      "z": -42,
      "name": "Cloth_Block_Wool_Gray_Light"
    },
    {
      "x": -111,
      "y": 33,
      "z": -41,
      "name": "Cloth_Block_Wool_Gray_Light"
    },
    {
      "x": -111,
      "y": 33,
      "z": -40,
      "name": "Cloth_Block_Wool_Gray_Light"
    },
    {
      "x": -111,
      "y": 33,
      "z": -39,
      "name": "Cloth_Block_Wool_Gray_Light"
    },
    {
      "x": -111,
      "y": 33,
      "z": -38,
      "name": "Cloth_Block_Wool_Gray_Light"
    },
    {
      "x": -111,
      "y": 33,
      "z": -37,
      "name": "Cloth_Block_Wool_Gray_Light"
    },
    {
      "x": -111,
      "y": 33,
      "z": -36,
      "name": "Cloth_Block_Wool_Gray_Light"
    },
    {
      "x": -111,
      "y": 33,
      "z": -35,
      "name": "Cloth_Block_Wool_Gray_Light"
    },
    {
      "x": -111,
      "y": 33,
      "z": -34,
      "name": "Cloth_Block_Wool_Gray_Light"
    },
    {
      "x": -111,
      "y": 33,
      "z": -33,
      "name": "Cloth_Block_Wool_Gray_Light"
    },
    {
      "x": -111,
      "y": 33,
      "z": -32,
      "name": "Cloth_Block_Wool_Gray_Light"
    },
    {
      "x": -111,
      "y": 33,
      "z": -31,
      "name": "Cloth_Block_Wool_Gray_Light"
    },
    {
      "x": -111,
      "y": 33,
      "z": -30,
      "name": "Cloth_Block_Wool_Gray_Light"
    },
    {
      "x": -111,
      "y": 33,
      "z": -29,
      "name": "Cloth_Block_Wool_Gray_Light"
    },
    {
      "x": -111,
      "y": 33,
      "z": -28,
      "name": "Cloth_Block_Wool_Gray_Light"
    },
    {
      "x": -111,
      "y": 33,
      "z": -27,
      "name": "Cloth_Block_Wool_Gray_Light"
    },
    {
      "x": -111,
      "y": 33,
      "z": -26,
      "name": "Cloth_Block_Wool_Gray_Light"
    },
    {
      "x": -111,
      "y": 33,
      "z": -25,
      "name": "Cloth_Block_Wool_Gray_Light"
    },
    {
      "x": -111,
      "y": 33,
      "z": -24,
      "name": "Cloth_Block_Wool_Gray_Light"
    },
    {
      "x": -111,
      "y": 33,
      "z": -23,
      "name": "Cloth_Block_Wool_Gray_Light"
    },
    {
      "x": -111,
      "y": 33,
      "z": -22,
      "name": "Cloth_Block_Wool_Gray_Light"
    },
    {
      "x": -111,
      "y": 33,
      "z": -21,
      "name": "Cloth_Block_Wool_Gray_Light"
    },
    {
      "x": -111,
      "y": 33,
      "z": -20,
      "name": "Cloth_Block_Wool_Gray_Light"
    },
    {
      "x": -111,
      "y": 33,
      "z": -19,
      "name": "Cloth_Block_Wool_Gray_Light"
    },
    {
      "x": -111,
      "y": 33,
      "z": -18,
      "name": "Cloth_Block_Wool_Gray_Light"
    },
    {
      "x": -111,
      "y": 33,
      "z": -17,
      "name": "Cloth_Block_Wool_Gray_Light"
    },
    {
      "x": -111,
      "y": 33,
      "z": -16,
      "name": "Cloth_Block_Wool_Gray_Light"
    },
    {
      "x": -111,
      "y": 33,
      "z": -15,
      "name": "Cloth_Block_Wool_Gray_Light"
    },
    {
      "x": -111,
      "y": 33,
      "z": -14,
      "name": "Cloth_Block_Wool_Gray_Light"
    },
    {
      "x": -111,
      "y": 33,
      "z": -13,
      "name": "Cloth_Block_Wool_Gray_Light"
    },
    {
      "x": -111,
      "y": 33,
